Workbook

Sheet Dashboard
A1: ✦ MeDa Partners | Dream · Deliver · Dominate Wayveda Inventory Dashboard | Warehouse Ops
A3: ⚠ Systems by MeDa Partners Pvt Ltd (www.meda.partners) | Brand: Wayveda® | Confidential & Proprietary
A4: Stock Health | D4: Monthly Dispatch | F4: Reorder | H4: Status
A6: Sr. | B6: Product Name | C6: ★ Balance (Current Stock) | D6: Last Month Dispatch | E6: This Month (So Far) | F6: Order Qty (Max − Balance) | G6: Latest Entry (Date + Qty) | H6: Status | I6: Alert
A7: 1 | B7: Bum Plumping Cream - 50g | C7: =Ledger!H7 -> 0 | D7: =IFERROR(SUMPRODUCT((MONTH('Daily Dispatch'!$A$7:$A$506)=IF(MONTH(TODAY())=1,12,MONTH(TODAY())-1))*(YEAR('Daily Dispatch'!$A$7:$A$506)=IF(MONTH(TODAY())=1,YEAR(TODAY())-1,YEAR(TODAY())))*ISNUMBER('Daily Dispatch'!$A$7:$A$506)*'Daily Dispatch'!B7:B506),0) -> 0 | E7: =IFERROR(SUMPRODUCT((MONTH('Daily Dispatch'!$A$7:$A$506)=MONTH(TODAY()))*(YEAR('Daily Dispatch'!$A$7:$A$506)=YEAR(TODAY()))*ISNUMBER('Daily Dispatch'!$A$7:$A$506)*'Daily Dispatch'!B7:B506),0) -> 0 | F7: =IFERROR(IF(Ledger!I7=0,"Set Max Level",MAX(0,Ledger!I7-Ledger!H7)),"—") -> Set Max Level | G7: =IFERROR(let(ldate,maxifs('Daily Dispatch'!$A$7:$A$506,'Daily Dispatch'!$A$7:$A$506,">0"),lqty,IFERROR(SUMIF('Daily Dispatch'!$A$7:$A$506,ldate,'Daily Dispatch'!B7:B506),0),datestr,IF(ldate=TODAY(),"Today",IF(ldate=TODAY()-1,"Yesterday",TEXT(ldate,"DD MMM"))),datestr&" — "&lqty&" units"),"No data yet") -> No data yet | H7: =IFERROR(IF(Ledger!I7=0,"⬜ Set Max Level",IF(Ledger!H7/Ledger!I7>1,"✅ Above Target",IF(Ledger!H7/Ledger!I7>=0.75,"✅ On Track",IF(Ledger!H7/Ledger!I7>=0.5,"🟡 Watch",IF(Ledger!H7/Ledger!I7>=0.25,"🔴 Low Stock","🔴 CRITICAL"))))),"—") -> ⬜ Set Max Level | I7: =IFERROR(IF(Ledger!I7=0,"—",IF(Ledger!H7<Ledger!I7*0.25,"🔴 ORDER NOW",IF(Ledger!H7<Ledger!I7*0.5,"⚠️ Plan Reorder","✅ OK"))),"—") -> —
A8: 2 | B8: Intimate Whitening Roll-On - 50ml | C8: =Ledger!H8 -> 0 | D8: =IFERROR(SUMPRODUCT((MONTH('Daily Dispatch'!$A$7:$A$506)=IF(MONTH(TODAY())=1,12,MONTH(TODAY())-1))*(YEAR('Daily Dispatch'!$A$7:$A$506)=IF(MONTH(TODAY())=1,YEAR(TODAY())-1,YEAR(TODAY())))*ISNUMBER('Daily Dispatch'!$A$7:$A$506)*'Daily Dispatch'!C7:C506),0) -> 0 | E8: =IFERROR(SUMPRODUCT((MONTH('Daily Dispatch'!$A$7:$A$506)=MONTH(TODAY()))*(YEAR('Daily Dispatch'!$A$7:$A$506)=YEAR(TODAY()))*ISNUMBER('Daily Dispatch'!$A$7:$A$506)*'Daily Dispatch'!C7:C506),0) -> 0 | F8: =IFERROR(IF(Ledger!I8=0,"Set Max Level",MAX(0,Ledger!I8-Ledger!H8)),"—") -> Set Max Level | G8: =IFERROR(let(ldate,maxifs('Daily Dispatch'!$A$7:$A$506,'Daily Dispatch'!$A$7:$A$506,">0"),lqty,IFERROR(SUMIF('Daily Dispatch'!$A$7:$A$506,ldate,'Daily Dispatch'!C7:C506),0),datestr,IF(ldate=TODAY(),"Today",IF(ldate=TODAY()-1,"Yesterday",TEXT(ldate,"DD MMM"))),datestr&" — "&lqty&" units"),"No data yet") -> No data yet | H8: =IFERROR(IF(Ledger!I8=0,"⬜ Set Max Level",IF(Ledger!H8/Ledger!I8>1,"✅ Above Target",IF(Ledger!H8/Ledger!I8>=0.75,"✅ On Track",IF(Ledger!H8/Ledger!I8>=0.5,"🟡 Watch",IF(Ledger!H8/Ledger!I8>=0.25,"🔴 Low Stock","🔴 CRITICAL"))))),"—") -> ⬜ Set Max Level | I8: =IFERROR(IF(Ledger!I8=0,"—",IF(Ledger!H8<Ledger!I8*0.25,"🔴 ORDER NOW",IF(Ledger!H8<Ledger!I8*0.5,"⚠️ Plan Reorder","✅ OK"))),"—") -> —
A9: 3 | B9: Chocolate Power Roll-On | C9: =Ledger!H9 -> 0 | D9: =IFERROR(SUMPRODUCT((MONTH('Daily Dispatch'!$A$7:$A$506)=IF(MONTH(TODAY())=1,12,MONTH(TODAY())-1))*(YEAR('Daily Dispatch'!$A$7:$A$506)=IF(MONTH(TODAY())=1,YEAR(TODAY())-1,YEAR(TODAY())))*ISNUMBER('Daily Dispatch'!$A$7:$A$506)*'Daily Dispatch'!D7:D506),0) -> 0 | E9: =IFERROR(SUMPRODUCT((MONTH('Daily Dispatch'!$A$7:$A$506)=MONTH(TODAY()))*(YEAR('Daily Dispatch'!$A$7:$A$506)=YEAR(TODAY()))*ISNUMBER('Daily Dispatch'!$A$7:$A$506)*'Daily Dispatch'!D7:D506),0) -> 0 | F9: =IFERROR(IF(Ledger!I9=0,"Set Max Level",MAX(0,Ledger!I9-Ledger!H9)),"—") -> Set Max Level | G9: =IFERROR(let(ldate,maxifs('Daily Dispatch'!$A$7:$A$506,'Daily Dispatch'!$A$7:$A$506,">0"),lqty,IFERROR(SUMIF('Daily Dispatch'!$A$7:$A$506,ldate,'Daily Dispatch'!D7:D506),0),datestr,IF(ldate=TODAY(),"Today",IF(ldate=TODAY()-1,"Yesterday",TEXT(ldate,"DD MMM"))),datestr&" — "&lqty&" units"),"No data yet") -> No data yet | H9: =IFERROR(IF(Ledger!I9=0,"⬜ Set Max Level",IF(Ledger!H9/Ledger!I9>1,"✅ Above Target",IF(Ledger!H9/Ledger!I9>=0.75,"✅ On Track",IF(Ledger!H9/Ledger!I9>=0.5,"🟡 Watch",IF(Ledger!H9/Ledger!I9>=0.25,"🔴 Low Stock","🔴 CRITICAL"))))),"—") -> ⬜ Set Max Level | I9: =IFERROR(IF(Ledger!I9=0,"—",IF(Ledger!H9<Ledger!I9*0.25,"🔴 ORDER NOW",IF(Ledger!H9<Ledger!I9*0.5,"⚠️ Plan Reorder","✅ OK"))),"—") -> —
A10: 4 | B10: Strawberry Power Roll-On | C10: =Ledger!H10 -> 0 | D10: =IFERROR(SUMPRODUCT((MONTH('Daily Dispatch'!$A$7:$A$506)=IF(MONTH(TODAY())=1,12,MONTH(TODAY())-1))*(YEAR('Daily Dispatch'!$A$7:$A$506)=IF(MONTH(TODAY())=1,YEAR(TODAY())-1,YEAR(TODAY())))*ISNUMBER('Daily Dispatch'!$A$7:$A$506)*'Daily Dispatch'!E7:E506),0) -> 0 | E10: =IFERROR(SUMPRODUCT((MONTH('Daily Dispatch'!$A$7:$A$506)=MONTH(TODAY()))*(YEAR('Daily Dispatch'!$A$7:$A$506)=YEAR(TODAY()))*ISNUMBER('Daily Dispatch'!$A$7:$A$506)*'Daily Dispatch'!E7:E506),0) -> 0 | F10: =IFERROR(IF(Ledger!I10=0,"Set Max Level",MAX(0,Ledger!I10-Ledger!H10)),"—") -> Set Max Level | G10: =IFERROR(let(ldate,maxifs('Daily Dispatch'!$A$7:$A$506,'Daily Dispatch'!$A$7:$A$506,">0"),lqty,IFERROR(SUMIF('Daily Dispatch'!$A$7:$A$506,ldate,'Daily Dispatch'!E7:E506),0),datestr,IF(ldate=TODAY(),"Today",IF(ldate=TODAY()-1,"Yesterday",TEXT(ldate,"DD MMM"))),datestr&" — "&lqty&" units"),"No data yet") -> No data yet | H10: =IFERROR(IF(Ledger!I10=0,"⬜ Set Max Level",IF(Ledger!H10/Ledger!I10>1,"✅ Above Target",IF(Ledger!H10/Ledger!I10>=0.75,"✅ On Track",IF(Ledger!H10/Ledger!I10>=0.5,"🟡 Watch",IF(Ledger!H10/Ledger!I10>=0.25,"🔴 Low Stock","🔴 CRITICAL"))))),"—") -> ⬜ Set Max Level | I10: =IFERROR(IF(Ledger!I10=0,"—",IF(Ledger!H10<Ledger!I10*0.25,"🔴 ORDER NOW",IF(Ledger!H10<Ledger!I10*0.5,"⚠️ Plan Reorder","✅ OK"))),"—") -> —
A11: 5 | B11: Bhasam Power Capsule | C11: =Ledger!H11 -> 0 | D11: =IFERROR(SUMPRODUCT((MONTH('Daily Dispatch'!$A$7:$A$506)=IF(MONTH(TODAY())=1,12,MONTH(TODAY())-1))*(YEAR('Daily Dispatch'!$A$7:$A$506)=IF(MONTH(TODAY())=1,YEAR(TODAY())-1,YEAR(TODAY())))*ISNUMBER('Daily Dispatch'!$A$7:$A$506)*'Daily Dispatch'!F7:F506),0) -> 0 | E11: =IFERROR(SUMPRODUCT((MONTH('Daily Dispatch'!$A$7:$A$506)=MONTH(TODAY()))*(YEAR('Daily Dispatch'!$A$7:$A$506)=YEAR(TODAY()))*ISNUMBER('Daily Dispatch'!$A$7:$A$506)*'Daily Dispatch'!F7:F506),0) -> 0 | F11: =IFERROR(IF(Ledger!I11=0,"Set Max Level",MAX(0,Ledger!I11-Ledger!H11)),"—") -> Set Max Level | G11: =IFERROR(let(ldate,maxifs('Daily Dispatch'!$A$7:$A$506,'Daily Dispatch'!$A$7:$A$506,">0"),lqty,IFERROR(SUMIF('Daily Dispatch'!$A$7:$A$506,ldate,'Daily Dispatch'!F7:F506),0),datestr,IF(ldate=TODAY(),"Today",IF(ldate=TODAY()-1,"Yesterday",TEXT(ldate,"DD MMM"))),datestr&" — "&lqty&" units"),"No data yet") -> No data yet | H11: =IFERROR(IF(Ledger!I11=0,"⬜ Set Max Level",IF(Ledger!H11/Ledger!I11>1,"✅ Above Target",IF(Ledger!H11/Ledger!I11>=0.75,"✅ On Track",IF(Ledger!H11/Ledger!I11>=0.5,"🟡 Watch",IF(Ledger!H11/Ledger!I11>=0.25,"🔴 Low Stock","🔴 CRITICAL"))))),"—") -> ⬜ Set Max Level | I11: =IFERROR(IF(Ledger!I11=0,"—",IF(Ledger!H11<Ledger!I11*0.25,"🔴 ORDER NOW",IF(Ledger!H11<Ledger!I11*0.5,"⚠️ Plan Reorder","✅ OK"))),"—") -> —
A12: 6 | B12: Power Shots Sachet | C12: =Ledger!H12 -> 0 | D12: =IFERROR(SUMPRODUCT((MONTH('Daily Dispatch'!$A$7:$A$506)=IF(MONTH(TODAY())=1,12,MONTH(TODAY())-1))*(YEAR('Daily Dispatch'!$A$7:$A$506)=IF(MONTH(TODAY())=1,YEAR(TODAY())-1,YEAR(TODAY())))*ISNUMBER('Daily Dispatch'!$A$7:$A$506)*'Daily Dispatch'!G7:G506),0) -> 0 | E12: =IFERROR(SUMPRODUCT((MONTH('Daily Dispatch'!$A$7:$A$506)=MONTH(TODAY()))*(YEAR('Daily Dispatch'!$A$7:$A$506)=YEAR(TODAY()))*ISNUMBER('Daily Dispatch'!$A$7:$A$506)*'Daily Dispatch'!G7:G506),0) -> 0 | F12: =IFERROR(IF(Ledger!I12=0,"Set Max Level",MAX(0,Ledger!I12-Ledger!H12)),"—") -> Set Max Level | G12: =IFERROR(let(ldate,maxifs('Daily Dispatch'!$A$7:$A$506,'Daily Dispatch'!$A$7:$A$506,">0"),lqty,IFERROR(SUMIF('Daily Dispatch'!$A$7:$A$506,ldate,'Daily Dispatch'!G7:G506),0),datestr,IF(ldate=TODAY(),"Today",IF(ldate=TODAY()-1,"Yesterday",TEXT(ldate,"DD MMM"))),datestr&" — "&lqty&" units"),"No data yet") -> No data yet | H12: =IFERROR(IF(Ledger!I12=0,"⬜ Set Max Level",IF(Ledger!H12/Ledger!I12>1,"✅ Above Target",IF(Ledger!H12/Ledger!I12>=0.75,"✅ On Track",IF(Ledger!H12/Ledger!I12>=0.5,"🟡 Watch",IF(Ledger!H12/Ledger!I12>=0.25,"🔴 Low Stock","🔴 CRITICAL"))))),"—") -> ⬜ Set Max Level | I12: =IFERROR(IF(Ledger!I12=0,"—",IF(Ledger!H12<Ledger!I12*0.25,"🔴 ORDER NOW",IF(Ledger!H12<Ledger!I12*0.5,"⚠️ Plan Reorder","✅ OK"))),"—") -> —
A13: 7 | B13: Hairfall Control Serum - 50ml | C13: =Ledger!H13 -> 0 | D13: =IFERROR(SUMPRODUCT((MONTH('Daily Dispatch'!$A$7:$A$506)=IF(MONTH(TODAY())=1,12,MONTH(TODAY())-1))*(YEAR('Daily Dispatch'!$A$7:$A$506)=IF(MONTH(TODAY())=1,YEAR(TODAY())-1,YEAR(TODAY())))*ISNUMBER('Daily Dispatch'!$A$7:$A$506)*'Daily Dispatch'!H7:H506),0) -> 0 | E13: =IFERROR(SUMPRODUCT((MONTH('Daily Dispatch'!$A$7:$A$506)=MONTH(TODAY()))*(YEAR('Daily Dispatch'!$A$7:$A$506)=YEAR(TODAY()))*ISNUMBER('Daily Dispatch'!$A$7:$A$506)*'Daily Dispatch'!H7:H506),0) -> 0 | F13: =IFERROR(IF(Ledger!I13=0,"Set Max Level",MAX(0,Ledger!I13-Ledger!H13)),"—") -> Set Max Level | G13: =IFERROR(let(ldate,maxifs('Daily Dispatch'!$A$7:$A$506,'Daily Dispatch'!$A$7:$A$506,">0"),lqty,IFERROR(SUMIF('Daily Dispatch'!$A$7:$A$506,ldate,'Daily Dispatch'!H7:H506),0),datestr,IF(ldate=TODAY(),"Today",IF(ldate=TODAY()-1,"Yesterday",TEXT(ldate,"DD MMM"))),datestr&" — "&lqty&" units"),"No data yet") -> No data yet | H13: =IFERROR(IF(Ledger!I13=0,"⬜ Set Max Level",IF(Ledger!H13/Ledger!I13>1,"✅ Above Target",IF(Ledger!H13/Ledger!I13>=0.75,"✅ On Track",IF(Ledger!H13/Ledger!I13>=0.5,"🟡 Watch",IF(Ledger!H13/Ledger!I13>=0.25,"🔴 Low Stock","🔴 CRITICAL"))))),"—") -> ⬜ Set Max Level | I13: =IFERROR(IF(Ledger!I13=0,"—",IF(Ledger!H13<Ledger!I13*0.25,"🔴 ORDER NOW",IF(Ledger!H13<Ledger!I13*0.5,"⚠️ Plan Reorder","✅ OK"))),"—") -> —
A14: 8 | B14: Hairfall Control Shampoo - 200ml | C14: =Ledger!H14 -> 0 | D14: =IFERROR(SUMPRODUCT((MONTH('Daily Dispatch'!$A$7:$A$506)=IF(MONTH(TODAY())=1,12,MONTH(TODAY())-1))*(YEAR('Daily Dispatch'!$A$7:$A$506)=IF(MONTH(TODAY())=1,YEAR(TODAY())-1,YEAR(TODAY())))*ISNUMBER('Daily Dispatch'!$A$7:$A$506)*'Daily Dispatch'!I7:I506),0) -> 0 | E14: =IFERROR(SUMPRODUCT((MONTH('Daily Dispatch'!$A$7:$A$506)=MONTH(TODAY()))*(YEAR('Daily Dispatch'!$A$7:$A$506)=YEAR(TODAY()))*ISNUMBER('Daily Dispatch'!$A$7:$A$506)*'Daily Dispatch'!I7:I506),0) -> 0 | F14: =IFERROR(IF(Ledger!I14=0,"Set Max Level",MAX(0,Ledger!I14-Ledger!H14)),"—") -> Set Max Level | G14: =IFERROR(let(ldate,maxifs('Daily Dispatch'!$A$7:$A$506,'Daily Dispatch'!$A$7:$A$506,">0"),lqty,IFERROR(SUMIF('Daily Dispatch'!$A$7:$A$506,ldate,'Daily Dispatch'!I7:I506),0),datestr,IF(ldate=TODAY(),"Today",IF(ldate=TODAY()-1,"Yesterday",TEXT(ldate,"DD MMM"))),datestr&" — "&lqty&" units"),"No data yet") -> No data yet | H14: =IFERROR(IF(Ledger!I14=0,"⬜ Set Max Level",IF(Ledger!H14/Ledger!I14>1,"✅ Above Target",IF(Ledger!H14/Ledger!I14>=0.75,"✅ On Track",IF(Ledger!H14/Ledger!I14>=0.5,"🟡 Watch",IF(Ledger!H14/Ledger!I14>=0.25,"🔴 Low Stock","🔴 CRITICAL"))))),"—") -> ⬜ Set Max Level | I14: =IFERROR(IF(Ledger!I14=0,"—",IF(Ledger!H14<Ledger!I14*0.25,"🔴 ORDER NOW",IF(Ledger!H14<Ledger!I14*0.5,"⚠️ Plan Reorder","✅ OK"))),"—") -> —
A15: 9 | B15: Hairfall Control Tablets - 60N | C15: =Ledger!H15 -> 0 | D15: =IFERROR(SUMPRODUCT((MONTH('Daily Dispatch'!$A$7:$A$506)=IF(MONTH(TODAY())=1,12,MONTH(TODAY())-1))*(YEAR('Daily Dispatch'!$A$7:$A$506)=IF(MONTH(TODAY())=1,YEAR(TODAY())-1,YEAR(TODAY())))*ISNUMBER('Daily Dispatch'!$A$7:$A$506)*'Daily Dispatch'!J7:J506),0) -> 0 | E15: =IFERROR(SUMPRODUCT((MONTH('Daily Dispatch'!$A$7:$A$506)=MONTH(TODAY()))*(YEAR('Daily Dispatch'!$A$7:$A$506)=YEAR(TODAY()))*ISNUMBER('Daily Dispatch'!$A$7:$A$506)*'Daily Dispatch'!J7:J506),0) -> 0 | F15: =IFERROR(IF(Ledger!I15=0,"Set Max Level",MAX(0,Ledger!I15-Ledger!H15)),"—") -> Set Max Level | G15: =IFERROR(let(ldate,maxifs('Daily Dispatch'!$A$7:$A$506,'Daily Dispatch'!$A$7:$A$506,">0"),lqty,IFERROR(SUMIF('Daily Dispatch'!$A$7:$A$506,ldate,'Daily Dispatch'!J7:J506),0),datestr,IF(ldate=TODAY(),"Today",IF(ldate=TODAY()-1,"Yesterday",TEXT(ldate,"DD MMM"))),datestr&" — "&lqty&" units"),"No data yet") -> No data yet | H15: =IFERROR(IF(Ledger!I15=0,"⬜ Set Max Level",IF(Ledger!H15/Ledger!I15>1,"✅ Above Target",IF(Ledger!H15/Ledger!I15>=0.75,"✅ On Track",IF(Ledger!H15/Ledger!I15>=0.5,"🟡 Watch",IF(Ledger!H15/Ledger!I15>=0.25,"🔴 Low Stock","🔴 CRITICAL"))))),"—") -> ⬜ Set Max Level | I15: =IFERROR(IF(Ledger!I15=0,"—",IF(Ledger!H15<Ledger!I15*0.25,"🔴 ORDER NOW",IF(Ledger!H15<Ledger!I15*0.5,"⚠️ Plan Reorder","✅ OK"))),"—") -> —
A16: 10 | B16: Anti-Hairfall Kit | C16: =Ledger!H16 -> 0 | D16: =IFERROR(SUMPRODUCT((MONTH('Daily Dispatch'!$A$7:$A$506)=IF(MONTH(TODAY())=1,12,MONTH(TODAY())-1))*(YEAR('Daily Dispatch'!$A$7:$A$506)=IF(MONTH(TODAY())=1,YEAR(TODAY())-1,YEAR(TODAY())))*ISNUMBER('Daily Dispatch'!$A$7:$A$506)*'Daily Dispatch'!K7:K506),0) -> 0 | E16: =IFERROR(SUMPRODUCT((MONTH('Daily Dispatch'!$A$7:$A$506)=MONTH(TODAY()))*(YEAR('Daily Dispatch'!$A$7:$A$506)=YEAR(TODAY()))*ISNUMBER('Daily Dispatch'!$A$7:$A$506)*'Daily Dispatch'!K7:K506),0) -> 0 | F16: =IFERROR(IF(Ledger!I16=0,"Set Max Level",MAX(0,Ledger!I16-Ledger!H16)),"—") -> Set Max Level | G16: =IFERROR(let(ldate,maxifs('Daily Dispatch'!$A$7:$A$506,'Daily Dispatch'!$A$7:$A$506,">0"),lqty,IFERROR(SUMIF('Daily Dispatch'!$A$7:$A$506,ldate,'Daily Dispatch'!K7:K506),0),datestr,IF(ldate=TODAY(),"Today",IF(ldate=TODAY()-1,"Yesterday",TEXT(ldate,"DD MMM"))),datestr&" — "&lqty&" units"),"No data yet") -> No data yet | H16: =IFERROR(IF(Ledger!I16=0,"⬜ Set Max Level",IF(Ledger!H16/Ledger!I16>1,"✅ Above Target",IF(Ledger!H16/Ledger!I16>=0.75,"✅ On Track",IF(Ledger!H16/Ledger!I16>=0.5,"🟡 Watch",IF(Ledger!H16/Ledger!I16>=0.25,"🔴 Low Stock","🔴 CRITICAL"))))),"—") -> ⬜ Set Max Level | I16: =IFERROR(IF(Ledger!I16=0,"—",IF(Ledger!H16<Ledger!I16*0.25,"🔴 ORDER NOW",IF(Ledger!H16<Ledger!I16*0.5,"⚠️ Plan Reorder","✅ OK"))),"—") -> —
A17: 11 | B17: Power Roll Oil Unflavoured | C17: =Ledger!H17 -> 0 | D17: =IFERROR(SUMPRODUCT((MONTH('Daily Dispatch'!$A$7:$A$506)=IF(MONTH(TODAY())=1,12,MONTH(TODAY())-1))*(YEAR('Daily Dispatch'!$A$7:$A$506)=IF(MONTH(TODAY())=1,YEAR(TODAY())-1,YEAR(TODAY())))*ISNUMBER('Daily Dispatch'!$A$7:$A$506)*'Daily Dispatch'!L7:L506),0) -> 0 | E17: =IFERROR(SUMPRODUCT((MONTH('Daily Dispatch'!$A$7:$A$506)=MONTH(TODAY()))*(YEAR('Daily Dispatch'!$A$7:$A$506)=YEAR(TODAY()))*ISNUMBER('Daily Dispatch'!$A$7:$A$506)*'Daily Dispatch'!L7:L506),0) -> 0 | F17: =IFERROR(IF(Ledger!I17=0,"Set Max Level",MAX(0,Ledger!I17-Ledger!H17)),"—") -> Set Max Level | G17: =IFERROR(let(ldate,maxifs('Daily Dispatch'!$A$7:$A$506,'Daily Dispatch'!$A$7:$A$506,">0"),lqty,IFERROR(SUMIF('Daily Dispatch'!$A$7:$A$506,ldate,'Daily Dispatch'!L7:L506),0),datestr,IF(ldate=TODAY(),"Today",IF(ldate=TODAY()-1,"Yesterday",TEXT(ldate,"DD MMM"))),datestr&" — "&lqty&" units"),"No data yet") -> No data yet | H17: =IFERROR(IF(Ledger!I17=0,"⬜ Set Max Level",IF(Ledger!H17/Ledger!I17>1,"✅ Above Target",IF(Ledger!H17/Ledger!I17>=0.75,"✅ On Track",IF(Ledger!H17/Ledger!I17>=0.5,"🟡 Watch",IF(Ledger!H17/Ledger!I17>=0.25,"🔴 Low Stock","🔴 CRITICAL"))))),"—") -> ⬜ Set Max Level | I17: =IFERROR(IF(Ledger!I17=0,"—",IF(Ledger!H17<Ledger!I17*0.25,"🔴 ORDER NOW",IF(Ledger!H17<Ledger!I17*0.5,"⚠️ Plan Reorder","✅ OK"))),"—") -> —
A18: 12 | B18: Power Shot Oil | C18: =Ledger!H18 -> 0 | D18: =IFERROR(SUMPRODUCT((MONTH('Daily Dispatch'!$A$7:$A$506)=IF(MONTH(TODAY())=1,12,MONTH(TODAY())-1))*(YEAR('Daily Dispatch'!$A$7:$A$506)=IF(MONTH(TODAY())=1,YEAR(TODAY())-1,YEAR(TODAY())))*ISNUMBER('Daily Dispatch'!$A$7:$A$506)*'Daily Dispatch'!M7:M506),0) -> 0 | E18: =IFERROR(SUMPRODUCT((MONTH('Daily Dispatch'!$A$7:$A$506)=MONTH(TODAY()))*(YEAR('Daily Dispatch'!$A$7:$A$506)=YEAR(TODAY()))*ISNUMBER('Daily Dispatch'!$A$7:$A$506)*'Daily Dispatch'!M7:M506),0) -> 0 | F18: =IFERROR(IF(Ledger!I18=0,"Set Max Level",MAX(0,Ledger!I18-Ledger!H18)),"—") -> Set Max Level | G18: =IFERROR(let(ldate,maxifs('Daily Dispatch'!$A$7:$A$506,'Daily Dispatch'!$A$7:$A$506,">0"),lqty,IFERROR(SUMIF('Daily Dispatch'!$A$7:$A$506,ldate,'Daily Dispatch'!M7:M506),0),datestr,IF(ldate=TODAY(),"Today",IF(ldate=TODAY()-1,"Yesterday",TEXT(ldate,"DD MMM"))),datestr&" — "&lqty&" units"),"No data yet") -> No data yet | H18: =IFERROR(IF(Ledger!I18=0,"⬜ Set Max Level",IF(Ledger!H18/Ledger!I18>1,"✅ Above Target",IF(Ledger!H18/Ledger!I18>=0.75,"✅ On Track",IF(Ledger!H18/Ledger!I18>=0.5,"🟡 Watch",IF(Ledger!H18/Ledger!I18>=0.25,"🔴 Low Stock","🔴 CRITICAL"))))),"—") -> ⬜ Set Max Level | I18: =IFERROR(IF(Ledger!I18=0,"—",IF(Ledger!H18<Ledger!I18*0.25,"🔴 ORDER NOW",IF(Ledger!H18<Ledger!I18*0.5,"⚠️ Plan Reorder","✅ OK"))),"—") -> —
A21: Last Updated by Vendor: — (auto-updates when Google Form is submitted)
A23: © 2026 MeDa Partners Pvt Ltd · Systems by MeDa Partners · Brand: Wayveda® · www.meda.partners · Dream. Deliver. Dominate.

Sheet Ledger
A1: ✦ MeDa Partners | Dream · Deliver · Dominate Wayveda Inventory Ledger | Warehouse Ops — Full Detail
A3: ⚠ Systems by MeDa Partners Pvt Ltd (www.meda.partners) | Brand: Wayveda® | Confidential & Proprietary
A4: Section 1 — Stock Movement | H4: Section 2 — Targets & Health | L4: Section 3 — Monthly Dispatch | O4: Section 4 — RTO Quality | R4: Reorder
A6: Sr. | B6: Product Name | C6: Opening Stock ⚠ Fill Once | D6: Total Stock Received | E6: Total Dispatched | F6: RTO Right (Recovered +) | G6: RTO Wrong+Fake (Lost −) | H6: ★ BALANCE (Current) | I6: Max Level ★ Fill This | J6: Stock % | K6: Status | L6: Last Month Dispatch | M6: This Month (So Far) | N6: Latest Entry (Date + Qty) | O6: RTO Rate % | P6: Warehouse Fault % | Q6: Recoverable Units | R6: Order Qty (Max−Balance) | S6: Reorder Alert
A7: 1 | B7: Bum Plumping Cream - 50g | C7: 0 | D7: =IFERROR(SUM('Stock In'!F:F),0) -> 0 | E7: =IFERROR(SUM('Daily Dispatch'!B:B),0) -> 0 | F7: =IFERROR(SUM('RTO Log'!B:B),0) -> 0 | G7: =IFERROR(SUM('RTO Log'!C:C)+SUM('RTO Log'!D:D),0) -> 0 | H7: =C7+D7+F7-G7-E7 -> 0 | J7: =IFERROR(IF(I7=0,"—",TEXT(ROUND(H7/I7*100,1),"0.0")&"%"),"—") -> — | K7: =IFERROR(IF(I7=0,"⬜ Set Max Level",IF(H7/I7>1,"✅ Above Target",IF(H7/I7>=0.75,"✅ On Track",IF(H7/I7>=0.5,"🟡 Watch",IF(H7/I7>=0.25,"🔴 Low Stock","🔴 CRITICAL"))))),"—") -> ⬜ Set Max Level | L7: =IFERROR(SUMPRODUCT((MONTH('Daily Dispatch'!$A$7:$A$506)=IF(MONTH(TODAY())=1,12,MONTH(TODAY())-1))*(YEAR('Daily Dispatch'!$A$7:$A$506)=IF(MONTH(TODAY())=1,YEAR(TODAY())-1,YEAR(TODAY())))*ISNUMBER('Daily Dispatch'!$A$7:$A$506)*'Daily Dispatch'!B7:B506),0) -> 0 | M7: =IFERROR(SUMPRODUCT((MONTH('Daily Dispatch'!$A$7:$A$506)=MONTH(TODAY()))*(YEAR('Daily Dispatch'!$A$7:$A$506)=YEAR(TODAY()))*ISNUMBER('Daily Dispatch'!$A$7:$A$506)*'Daily Dispatch'!B7:B506),0) -> 0 | N7: =IFERROR(let(ldate,maxifs('Daily Dispatch'!$A$7:$A$506,'Daily Dispatch'!$A$7:$A$506,">0"),lqty,IFERROR(SUMIF('Daily Dispatch'!$A$7:$A$506,ldate,'Daily Dispatch'!B7:B506),0),datestr,IF(ldate=TODAY(),"Today",IF(ldate=TODAY()-1,"Yesterday",TEXT(ldate,"DD MMM"))),datestr&" — "&lqty&" units"),"No data yet") -> No data yet | O7: =IFERROR(IF(E7=0,"—",TEXT(ROUND((F7+G7)/E7*100,1),"0.0")&"%"),"—") -> — | P7: =IFERROR(IF(E7=0,"—",TEXT(ROUND(G7/E7*100,1),"0.0")&"%"),"—") -> — | Q7: =F7 -> 0 | R7: =IFERROR(IF(I7=0,"Set Max Level",MAX(0,I7-H7)),"—") -> Set Max Level | S7: =IFERROR(IF(I7=0,"—",IF(H7<I7*0.25,"🔴 ORDER NOW",IF(H7<I7*0.5,"⚠️ Plan Reorder","✅ OK"))),"—") -> —
A8: 2 | B8: Intimate Whitening Roll-On - 50ml | C8: 0 | D8: =IFERROR(SUM('Stock In'!I:I),0) -> 0 | E8: =IFERROR(SUM('Daily Dispatch'!C:C),0) -> 0 | F8: =IFERROR(SUM('RTO Log'!E:E),0) -> 0 | G8: =IFERROR(SUM('RTO Log'!F:F)+SUM('RTO Log'!G:G),0) -> 0 | H8: =C8+D8+F8-G8-E8 -> 0 | J8: =IFERROR(IF(I8=0,"—",TEXT(ROUND(H8/I8*100,1),"0.0")&"%"),"—") -> — | K8: =IFERROR(IF(I8=0,"⬜ Set Max Level",IF(H8/I8>1,"✅ Above Target",IF(H8/I8>=0.75,"✅ On Track",IF(H8/I8>=0.5,"🟡 Watch",IF(H8/I8>=0.25,"🔴 Low Stock","🔴 CRITICAL"))))),"—") -> ⬜ Set Max Level | L8: =IFERROR(SUMPRODUCT((MONTH('Daily Dispatch'!$A$7:$A$506)=IF(MONTH(TODAY())=1,12,MONTH(TODAY())-1))*(YEAR('Daily Dispatch'!$A$7:$A$506)=IF(MONTH(TODAY())=1,YEAR(TODAY())-1,YEAR(TODAY())))*ISNUMBER('Daily Dispatch'!$A$7:$A$506)*'Daily Dispatch'!C7:C506),0) -> 0 | M8: =IFERROR(SUMPRODUCT((MONTH('Daily Dispatch'!$A$7:$A$506)=MONTH(TODAY()))*(YEAR('Daily Dispatch'!$A$7:$A$506)=YEAR(TODAY()))*ISNUMBER('Daily Dispatch'!$A$7:$A$506)*'Daily Dispatch'!C7:C506),0) -> 0 | N8: =IFERROR(let(ldate,maxifs('Daily Dispatch'!$A$7:$A$506,'Daily Dispatch'!$A$7:$A$506,">0"),lqty,IFERROR(SUMIF('Daily Dispatch'!$A$7:$A$506,ldate,'Daily Dispatch'!C7:C506),0),datestr,IF(ldate=TODAY(),"Today",IF(ldate=TODAY()-1,"Yesterday",TEXT(ldate,"DD MMM"))),datestr&" — "&lqty&" units"),"No data yet") -> No data yet | O8: =IFERROR(IF(E8=0,"—",TEXT(ROUND((F8+G8)/E8*100,1),"0.0")&"%"),"—") -> — | P8: =IFERROR(IF(E8=0,"—",TEXT(ROUND(G8/E8*100,1),"0.0")&"%"),"—") -> — | Q8: =F8 -> 0 | R8: =IFERROR(IF(I8=0,"Set Max Level",MAX(0,I8-H8)),"—") -> Set Max Level | S8: =IFERROR(IF(I8=0,"—",IF(H8<I8*0.25,"🔴 ORDER NOW",IF(H8<I8*0.5,"⚠️ Plan Reorder","✅ OK"))),"—") -> —
A9: 3 | B9: Chocolate Power Roll-On | C9: 0 | D9: =IFERROR(SUM('Stock In'!L:L),0) -> 0 | E9: =IFERROR(SUM('Daily Dispatch'!D:D),0) -> 0 | F9: =IFERROR(SUM('RTO Log'!H:H),0) -> 0 | G9: =IFERROR(SUM('RTO Log'!I:I)+SUM('RTO Log'!J:J),0) -> 0 | H9: =C9+D9+F9-G9-E9 -> 0 | J9: =IFERROR(IF(I9=0,"—",TEXT(ROUND(H9/I9*100,1),"0.0")&"%"),"—") -> — | K9: =IFERROR(IF(I9=0,"⬜ Set Max Level",IF(H9/I9>1,"✅ Above Target",IF(H9/I9>=0.75,"✅ On Track",IF(H9/I9>=0.5,"🟡 Watch",IF(H9/I9>=0.25,"🔴 Low Stock","🔴 CRITICAL"))))),"—") -> ⬜ Set Max Level | L9: =IFERROR(SUMPRODUCT((MONTH('Daily Dispatch'!$A$7:$A$506)=IF(MONTH(TODAY())=1,12,MONTH(TODAY())-1))*(YEAR('Daily Dispatch'!$A$7:$A$506)=IF(MONTH(TODAY())=1,YEAR(TODAY())-1,YEAR(TODAY())))*ISNUMBER('Daily Dispatch'!$A$7:$A$506)*'Daily Dispatch'!D7:D506),0) -> 0 | M9: =IFERROR(SUMPRODUCT((MONTH('Daily Dispatch'!$A$7:$A$506)=MONTH(TODAY()))*(YEAR('Daily Dispatch'!$A$7:$A$506)=YEAR(TODAY()))*ISNUMBER('Daily Dispatch'!$A$7:$A$506)*'Daily Dispatch'!D7:D506),0) -> 0 | N9: =IFERROR(let(ldate,maxifs('Daily Dispatch'!$A$7:$A$506,'Daily Dispatch'!$A$7:$A$506,">0"),lqty,IFERROR(SUMIF('Daily Dispatch'!$A$7:$A$506,ldate,'Daily Dispatch'!D7:D506),0),datestr,IF(ldate=TODAY(),"Today",IF(ldate=TODAY()-1,"Yesterday",TEXT(ldate,"DD MMM"))),datestr&" — "&lqty&" units"),"No data yet") -> No data yet | O9: =IFERROR(IF(E9=0,"—",TEXT(ROUND((F9+G9)/E9*100,1),"0.0")&"%"),"—") -> — | P9: =IFERROR(IF(E9=0,"—",TEXT(ROUND(G9/E9*100,1),"0.0")&"%"),"—") -> — | Q9: =F9 -> 0 | R9: =IFERROR(IF(I9=0,"Set Max Level",MAX(0,I9-H9)),"—") -> Set Max Level | S9: =IFERROR(IF(I9=0,"—",IF(H9<I9*0.25,"🔴 ORDER NOW",IF(H9<I9*0.5,"⚠️ Plan Reorder","✅ OK"))),"—") -> —
A10: 4 | B10: Strawberry Power Roll-On | C10: 0 | D10: =IFERROR(SUM('Stock In'!O:O),0) -> 0 | E10: =IFERROR(SUM('Daily Dispatch'!E:E),0) -> 0 | F10: =IFERROR(SUM('RTO Log'!K:K),0) -> 0 | G10: =IFERROR(SUM('RTO Log'!L:L)+SUM('RTO Log'!M:M),0) -> 0 | H10: =C10+D10+F10-G10-E10 -> 0 | J10: =IFERROR(IF(I10=0,"—",TEXT(ROUND(H10/I10*100,1),"0.0")&"%"),"—") -> — | K10: =IFERROR(IF(I10=0,"⬜ Set Max Level",IF(H10/I10>1,"✅ Above Target",IF(H10/I10>=0.75,"✅ On Track",IF(H10/I10>=0.5,"🟡 Watch",IF(H10/I10>=0.25,"🔴 Low Stock","🔴 CRITICAL"))))),"—") -> ⬜ Set Max Level | L10: =IFERROR(SUMPRODUCT((MONTH('Daily Dispatch'!$A$7:$A$506)=IF(MONTH(TODAY())=1,12,MONTH(TODAY())-1))*(YEAR('Daily Dispatch'!$A$7:$A$506)=IF(MONTH(TODAY())=1,YEAR(TODAY())-1,YEAR(TODAY())))*ISNUMBER('Daily Dispatch'!$A$7:$A$506)*'Daily Dispatch'!E7:E506),0) -> 0 | M10: =IFERROR(SUMPRODUCT((MONTH('Daily Dispatch'!$A$7:$A$506)=MONTH(TODAY()))*(YEAR('Daily Dispatch'!$A$7:$A$506)=YEAR(TODAY()))*ISNUMBER('Daily Dispatch'!$A$7:$A$506)*'Daily Dispatch'!E7:E506),0) -> 0 | N10: =IFERROR(let(ldate,maxifs('Daily Dispatch'!$A$7:$A$506,'Daily Dispatch'!$A$7:$A$506,">0"),lqty,IFERROR(SUMIF('Daily Dispatch'!$A$7:$A$506,ldate,'Daily Dispatch'!E7:E506),0),datestr,IF(ldate=TODAY(),"Today",IF(ldate=TODAY()-1,"Yesterday",TEXT(ldate,"DD MMM"))),datestr&" — "&lqty&" units"),"No data yet") -> No data yet | O10: =IFERROR(IF(E10=0,"—",TEXT(ROUND((F10+G10)/E10*100,1),"0.0")&"%"),"—") -> — | P10: =IFERROR(IF(E10=0,"—",TEXT(ROUND(G10/E10*100,1),"0.0")&"%"),"—") -> — | Q10: =F10 -> 0 | R10: =IFERROR(IF(I10=0,"Set Max Level",MAX(0,I10-H10)),"—") -> Set Max Level | S10: =IFERROR(IF(I10=0,"—",IF(H10<I10*0.25,"🔴 ORDER NOW",IF(H10<I10*0.5,"⚠️ Plan Reorder","✅ OK"))),"—") -> —
A11: 5 | B11: Bhasam Power Capsule | C11: 0 | D11: =IFERROR(SUM('Stock In'!R:R),0) -> 0 | E11: =IFERROR(SUM('Daily Dispatch'!F:F),0) -> 0 | F11: =IFERROR(SUM('RTO Log'!N:N),0) -> 0 | G11: =IFERROR(SUM('RTO Log'!O:O)+SUM('RTO Log'!P:P),0) -> 0 | H11: =C11+D11+F11-G11-E11 -> 0 | J11: =IFERROR(IF(I11=0,"—",TEXT(ROUND(H11/I11*100,1),"0.0")&"%"),"—") -> — | K11: =IFERROR(IF(I11=0,"⬜ Set Max Level",IF(H11/I11>1,"✅ Above Target",IF(H11/I11>=0.75,"✅ On Track",IF(H11/I11>=0.5,"🟡 Watch",IF(H11/I11>=0.25,"🔴 Low Stock","🔴 CRITICAL"))))),"—") -> ⬜ Set Max Level | L11: =IFERROR(SUMPRODUCT((MONTH('Daily Dispatch'!$A$7:$A$506)=IF(MONTH(TODAY())=1,12,MONTH(TODAY())-1))*(YEAR('Daily Dispatch'!$A$7:$A$506)=IF(MONTH(TODAY())=1,YEAR(TODAY())-1,YEAR(TODAY())))*ISNUMBER('Daily Dispatch'!$A$7:$A$506)*'Daily Dispatch'!F7:F506),0) -> 0 | M11: =IFERROR(SUMPRODUCT((MONTH('Daily Dispatch'!$A$7:$A$506)=MONTH(TODAY()))*(YEAR('Daily Dispatch'!$A$7:$A$506)=YEAR(TODAY()))*ISNUMBER('Daily Dispatch'!$A$7:$A$506)*'Daily Dispatch'!F7:F506),0) -> 0 | N11: =IFERROR(let(ldate,maxifs('Daily Dispatch'!$A$7:$A$506,'Daily Dispatch'!$A$7:$A$506,">0"),lqty,IFERROR(SUMIF('Daily Dispatch'!$A$7:$A$506,ldate,'Daily Dispatch'!F7:F506),0),datestr,IF(ldate=TODAY(),"Today",IF(ldate=TODAY()-1,"Yesterday",TEXT(ldate,"DD MMM"))),datestr&" — "&lqty&" units"),"No data yet") -> No data yet | O11: =IFERROR(IF(E11=0,"—",TEXT(ROUND((F11+G11)/E11*100,1),"0.0")&"%"),"—") -> — | P11: =IFERROR(IF(E11=0,"—",TEXT(ROUND(G11/E11*100,1),"0.0")&"%"),"—") -> — | Q11: =F11 -> 0 | R11: =IFERROR(IF(I11=0,"Set Max Level",MAX(0,I11-H11)),"—") -> Set Max Level | S11: =IFERROR(IF(I11=0,"—",IF(H11<I11*0.25,"🔴 ORDER NOW",IF(H11<I11*0.5,"⚠️ Plan Reorder","✅ OK"))),"—") -> —
A12: 6 | B12: Power Shots Sachet | C12: 0 | D12: =IFERROR(SUM('Stock In'!U:U),0) -> 0 | E12: =IFERROR(SUM('Daily Dispatch'!G:G),0) -> 0 | F12: =IFERROR(SUM('RTO Log'!Q:Q),0) -> 0 | G12: =IFERROR(SUM('RTO Log'!R:R)+SUM('RTO Log'!S:S),0) -> 0 | H12: =C12+D12+F12-G12-E12 -> 0 | J12: =IFERROR(IF(I12=0,"—",TEXT(ROUND(H12/I12*100,1),"0.0")&"%"),"—") -> — | K12: =IFERROR(IF(I12=0,"⬜ Set Max Level",IF(H12/I12>1,"✅ Above Target",IF(H12/I12>=0.75,"✅ On Track",IF(H12/I12>=0.5,"🟡 Watch",IF(H12/I12>=0.25,"🔴 Low Stock","🔴 CRITICAL"))))),"—") -> ⬜ Set Max Level | L12: =IFERROR(SUMPRODUCT((MONTH('Daily Dispatch'!$A$7:$A$506)=IF(MONTH(TODAY())=1,12,MONTH(TODAY())-1))*(YEAR('Daily Dispatch'!$A$7:$A$506)=IF(MONTH(TODAY())=1,YEAR(TODAY())-1,YEAR(TODAY())))*ISNUMBER('Daily Dispatch'!$A$7:$A$506)*'Daily Dispatch'!G7:G506),0) -> 0 | M12: =IFERROR(SUMPRODUCT((MONTH('Daily Dispatch'!$A$7:$A$506)=MONTH(TODAY()))*(YEAR('Daily Dispatch'!$A$7:$A$506)=YEAR(TODAY()))*ISNUMBER('Daily Dispatch'!$A$7:$A$506)*'Daily Dispatch'!G7:G506),0) -> 0 | N12: =IFERROR(let(ldate,maxifs('Daily Dispatch'!$A$7:$A$506,'Daily Dispatch'!$A$7:$A$506,">0"),lqty,IFERROR(SUMIF('Daily Dispatch'!$A$7:$A$506,ldate,'Daily Dispatch'!G7:G506),0),datestr,IF(ldate=TODAY(),"Today",IF(ldate=TODAY()-1,"Yesterday",TEXT(ldate,"DD MMM"))),datestr&" — "&lqty&" units"),"No data yet") -> No data yet | O12: =IFERROR(IF(E12=0,"—",TEXT(ROUND((F12+G12)/E12*100,1),"0.0")&"%"),"—") -> — | P12: =IFERROR(IF(E12=0,"—",TEXT(ROUND(G12/E12*100,1),"0.0")&"%"),"—") -> — | Q12: =F12 -> 0 | R12: =IFERROR(IF(I12=0,"Set Max Level",MAX(0,I12-H12)),"—") -> Set Max Level | S12: =IFERROR(IF(I12=0,"—",IF(H12<I12*0.25,"🔴 ORDER NOW",IF(H12<I12*0.5,"⚠️ Plan Reorder","✅ OK"))),"—") -> —
A13: 7 | B13: Hairfall Control Serum - 50ml | C13: 0 | D13: =IFERROR(SUM('Stock In'!X:X),0) -> 0 | E13: =IFERROR(SUM('Daily Dispatch'!H:H),0) -> 0 | F13: =IFERROR(SUM('RTO Log'!T:T),0) -> 0 | G13: =IFERROR(SUM('RTO Log'!U:U)+SUM('RTO Log'!V:V),0) -> 0 | H13: =C13+D13+F13-G13-E13 -> 0 | J13: =IFERROR(IF(I13=0,"—",TEXT(ROUND(H13/I13*100,1),"0.0")&"%"),"—") -> — | K13: =IFERROR(IF(I13=0,"⬜ Set Max Level",IF(H13/I13>1,"✅ Above Target",IF(H13/I13>=0.75,"✅ On Track",IF(H13/I13>=0.5,"🟡 Watch",IF(H13/I13>=0.25,"🔴 Low Stock","🔴 CRITICAL"))))),"—") -> ⬜ Set Max Level | L13: =IFERROR(SUMPRODUCT((MONTH('Daily Dispatch'!$A$7:$A$506)=IF(MONTH(TODAY())=1,12,MONTH(TODAY())-1))*(YEAR('Daily Dispatch'!$A$7:$A$506)=IF(MONTH(TODAY())=1,YEAR(TODAY())-1,YEAR(TODAY())))*ISNUMBER('Daily Dispatch'!$A$7:$A$506)*'Daily Dispatch'!H7:H506),0) -> 0 | M13: =IFERROR(SUMPRODUCT((MONTH('Daily Dispatch'!$A$7:$A$506)=MONTH(TODAY()))*(YEAR('Daily Dispatch'!$A$7:$A$506)=YEAR(TODAY()))*ISNUMBER('Daily Dispatch'!$A$7:$A$506)*'Daily Dispatch'!H7:H506),0) -> 0 | N13: =IFERROR(let(ldate,maxifs('Daily Dispatch'!$A$7:$A$506,'Daily Dispatch'!$A$7:$A$506,">0"),lqty,IFERROR(SUMIF('Daily Dispatch'!$A$7:$A$506,ldate,'Daily Dispatch'!H7:H506),0),datestr,IF(ldate=TODAY(),"Today",IF(ldate=TODAY()-1,"Yesterday",TEXT(ldate,"DD MMM"))),datestr&" — "&lqty&" units"),"No data yet") -> No data yet | O13: =IFERROR(IF(E13=0,"—",TEXT(ROUND((F13+G13)/E13*100,1),"0.0")&"%"),"—") -> — | P13: =IFERROR(IF(E13=0,"—",TEXT(ROUND(G13/E13*100,1),"0.0")&"%"),"—") -> — | Q13: =F13 -> 0 | R13: =IFERROR(IF(I13=0,"Set Max Level",MAX(0,I13-H13)),"—") -> Set Max Level | S13: =IFERROR(IF(I13=0,"—",IF(H13<I13*0.25,"🔴 ORDER NOW",IF(H13<I13*0.5,"⚠️ Plan Reorder","✅ OK"))),"—") -> —
A14: 8 | B14: Hairfall Control Shampoo - 200ml | C14: 0 | D14: =IFERROR(SUM('Stock In'!AA:AA),0) -> 0 | E14: =IFERROR(SUM('Daily Dispatch'!I:I),0) -> 0 | F14: =IFERROR(SUM('RTO Log'!W:W),0) -> 0 | G14: =IFERROR(SUM('RTO Log'!X:X)+SUM('RTO Log'!Y:Y),0) -> 0 | H14: =C14+D14+F14-G14-E14 -> 0 | J14: =IFERROR(IF(I14=0,"—",TEXT(ROUND(H14/I14*100,1),"0.0")&"%"),"—") -> — | K14: =IFERROR(IF(I14=0,"⬜ Set Max Level",IF(H14/I14>1,"✅ Above Target",IF(H14/I14>=0.75,"✅ On Track",IF(H14/I14>=0.5,"🟡 Watch",IF(H14/I14>=0.25,"🔴 Low Stock","🔴 CRITICAL"))))),"—") -> ⬜ Set Max Level | L14: =IFERROR(SUMPRODUCT((MONTH('Daily Dispatch'!$A$7:$A$506)=IF(MONTH(TODAY())=1,12,MONTH(TODAY())-1))*(YEAR('Daily Dispatch'!$A$7:$A$506)=IF(MONTH(TODAY())=1,YEAR(TODAY())-1,YEAR(TODAY())))*ISNUMBER('Daily Dispatch'!$A$7:$A$506)*'Daily Dispatch'!I7:I506),0) -> 0 | M14: =IFERROR(SUMPRODUCT((MONTH('Daily Dispatch'!$A$7:$A$506)=MONTH(TODAY()))*(YEAR('Daily Dispatch'!$A$7:$A$506)=YEAR(TODAY()))*ISNUMBER('Daily Dispatch'!$A$7:$A$506)*'Daily Dispatch'!I7:I506),0) -> 0 | N14: =IFERROR(let(ldate,maxifs('Daily Dispatch'!$A$7:$A$506,'Daily Dispatch'!$A$7:$A$506,">0"),lqty,IFERROR(SUMIF('Daily Dispatch'!$A$7:$A$506,ldate,'Daily Dispatch'!I7:I506),0),datestr,IF(ldate=TODAY(),"Today",IF(ldate=TODAY()-1,"Yesterday",TEXT(ldate,"DD MMM"))),datestr&" — "&lqty&" units"),"No data yet") -> No data yet | O14: =IFERROR(IF(E14=0,"—",TEXT(ROUND((F14+G14)/E14*100,1),"0.0")&"%"),"—") -> — | P14: =IFERROR(IF(E14=0,"—",TEXT(ROUND(G14/E14*100,1),"0.0")&"%"),"—") -> — | Q14: =F14 -> 0 | R14: =IFERROR(IF(I14=0,"Set Max Level",MAX(0,I14-H14)),"—") -> Set Max Level | S14: =IFERROR(IF(I14=0,"—",IF(H14<I14*0.25,"🔴 ORDER NOW",IF(H14<I14*0.5,"⚠️ Plan Reorder","✅ OK"))),"—") -> —
A15: 9 | B15: Hairfall Control Tablets - 60N | C15: 0 | D15: =IFERROR(SUM('Stock In'!AD:AD),0) -> 0 | E15: =IFERROR(SUM('Daily Dispatch'!J:J),0) -> 0 | F15: =IFERROR(SUM('RTO Log'!Z:Z),0) -> 0 | G15: =IFERROR(SUM('RTO Log'!AA:AA)+SUM('RTO Log'!AB:AB),0) -> 0 | H15: =C15+D15+F15-G15-E15 -> 0 | J15: =IFERROR(IF(I15=0,"—",TEXT(ROUND(H15/I15*100,1),"0.0")&"%"),"—") -> — | K15: =IFERROR(IF(I15=0,"⬜ Set Max Level",IF(H15/I15>1,"✅ Above Target",IF(H15/I15>=0.75,"✅ On Track",IF(H15/I15>=0.5,"🟡 Watch",IF(H15/I15>=0.25,"🔴 Low Stock","🔴 CRITICAL"))))),"—") -> ⬜ Set Max Level | L15: =IFERROR(SUMPRODUCT((MONTH('Daily Dispatch'!$A$7:$A$506)=IF(MONTH(TODAY())=1,12,MONTH(TODAY())-1))*(YEAR('Daily Dispatch'!$A$7:$A$506)=IF(MONTH(TODAY())=1,YEAR(TODAY())-1,YEAR(TODAY())))*ISNUMBER('Daily Dispatch'!$A$7:$A$506)*'Daily Dispatch'!J7:J506),0) -> 0 | M15: =IFERROR(SUMPRODUCT((MONTH('Daily Dispatch'!$A$7:$A$506)=MONTH(TODAY()))*(YEAR('Daily Dispatch'!$A$7:$A$506)=YEAR(TODAY()))*ISNUMBER('Daily Dispatch'!$A$7:$A$506)*'Daily Dispatch'!J7:J506),0) -> 0 | N15: =IFERROR(let(ldate,maxifs('Daily Dispatch'!$A$7:$A$506,'Daily Dispatch'!$A$7:$A$506,">0"),lqty,IFERROR(SUMIF('Daily Dispatch'!$A$7:$A$506,ldate,'Daily Dispatch'!J7:J506),0),datestr,IF(ldate=TODAY(),"Today",IF(ldate=TODAY()-1,"Yesterday",TEXT(ldate,"DD MMM"))),datestr&" — "&lqty&" units"),"No data yet") -> No data yet | O15: =IFERROR(IF(E15=0,"—",TEXT(ROUND((F15+G15)/E15*100,1),"0.0")&"%"),"—") -> — | P15: =IFERROR(IF(E15=0,"—",TEXT(ROUND(G15/E15*100,1),"0.0")&"%"),"—") -> — | Q15: =F15 -> 0 | R15: =IFERROR(IF(I15=0,"Set Max Level",MAX(0,I15-H15)),"—") -> Set Max Level | S15: =IFERROR(IF(I15=0,"—",IF(H15<I15*0.25,"🔴 ORDER NOW",IF(H15<I15*0.5,"⚠️ Plan Reorder","✅ OK"))),"—") -> —
A16: 10 | B16: Anti-Hairfall Kit | C16: 0 | D16: =IFERROR(SUM('Stock In'!AG:AG),0) -> 0 | E16: =IFERROR(SUM('Daily Dispatch'!K:K),0) -> 0 | F16: =IFERROR(SUM('RTO Log'!AC:AC),0) -> 0 | G16: =IFERROR(SUM('RTO Log'!AD:AD)+SUM('RTO Log'!AE:AE),0) -> 0 | H16: =C16+D16+F16-G16-E16 -> 0 | J16: =IFERROR(IF(I16=0,"—",TEXT(ROUND(H16/I16*100,1),"0.0")&"%"),"—") -> — | K16: =IFERROR(IF(I16=0,"⬜ Set Max Level",IF(H16/I16>1,"✅ Above Target",IF(H16/I16>=0.75,"✅ On Track",IF(H16/I16>=0.5,"🟡 Watch",IF(H16/I16>=0.25,"🔴 Low Stock","🔴 CRITICAL"))))),"—") -> ⬜ Set Max Level | L16: =IFERROR(SUMPRODUCT((MONTH('Daily Dispatch'!$A$7:$A$506)=IF(MONTH(TODAY())=1,12,MONTH(TODAY())-1))*(YEAR('Daily Dispatch'!$A$7:$A$506)=IF(MONTH(TODAY())=1,YEAR(TODAY())-1,YEAR(TODAY())))*ISNUMBER('Daily Dispatch'!$A$7:$A$506)*'Daily Dispatch'!K7:K506),0) -> 0 | M16: =IFERROR(SUMPRODUCT((MONTH('Daily Dispatch'!$A$7:$A$506)=MONTH(TODAY()))*(YEAR('Daily Dispatch'!$A$7:$A$506)=YEAR(TODAY()))*ISNUMBER('Daily Dispatch'!$A$7:$A$506)*'Daily Dispatch'!K7:K506),0) -> 0 | N16: =IFERROR(let(ldate,maxifs('Daily Dispatch'!$A$7:$A$506,'Daily Dispatch'!$A$7:$A$506,">0"),lqty,IFERROR(SUMIF('Daily Dispatch'!$A$7:$A$506,ldate,'Daily Dispatch'!K7:K506),0),datestr,IF(ldate=TODAY(),"Today",IF(ldate=TODAY()-1,"Yesterday",TEXT(ldate,"DD MMM"))),datestr&" — "&lqty&" units"),"No data yet") -> No data yet | O16: =IFERROR(IF(E16=0,"—",TEXT(ROUND((F16+G16)/E16*100,1),"0.0")&"%"),"—") -> — | P16: =IFERROR(IF(E16=0,"—",TEXT(ROUND(G16/E16*100,1),"0.0")&"%"),"—") -> — | Q16: =F16 -> 0 | R16: =IFERROR(IF(I16=0,"Set Max Level",MAX(0,I16-H16)),"—") -> Set Max Level | S16: =IFERROR(IF(I16=0,"—",IF(H16<I16*0.25,"🔴 ORDER NOW",IF(H16<I16*0.5,"⚠️ Plan Reorder","✅ OK"))),"—") -> —
A17: 11 | B17: Power Roll Oil Unflavoured | C17: 0 | D17: =IFERROR(SUM('Stock In'!AJ:AJ),0) -> 0 | E17: =IFERROR(SUM('Daily Dispatch'!L:L),0) -> 0 | F17: =IFERROR(SUM('RTO Log'!AF:AF),0) -> 0 | G17: =IFERROR(SUM('RTO Log'!AG:AG)+SUM('RTO Log'!AH:AH),0) -> 0 | H17: =C17+D17+F17-G17-E17 -> 0 | J17: =IFERROR(IF(I17=0,"—",TEXT(ROUND(H17/I17*100,1),"0.0")&"%"),"—") -> — | K17: =IFERROR(IF(I17=0,"⬜ Set Max Level",IF(H17/I17>1,"✅ Above Target",IF(H17/I17>=0.75,"✅ On Track",IF(H17/I17>=0.5,"🟡 Watch",IF(H17/I17>=0.25,"🔴 Low Stock","🔴 CRITICAL"))))),"—") -> ⬜ Set Max Level | L17: =IFERROR(SUMPRODUCT((MONTH('Daily Dispatch'!$A$7:$A$506)=IF(MONTH(TODAY())=1,12,MONTH(TODAY())-1))*(YEAR('Daily Dispatch'!$A$7:$A$506)=IF(MONTH(TODAY())=1,YEAR(TODAY())-1,YEAR(TODAY())))*ISNUMBER('Daily Dispatch'!$A$7:$A$506)*'Daily Dispatch'!L7:L506),0) -> 0 | M17: =IFERROR(SUMPRODUCT((MONTH('Daily Dispatch'!$A$7:$A$506)=MONTH(TODAY()))*(YEAR('Daily Dispatch'!$A$7:$A$506)=YEAR(TODAY()))*ISNUMBER('Daily Dispatch'!$A$7:$A$506)*'Daily Dispatch'!L7:L506),0) -> 0 | N17: =IFERROR(let(ldate,maxifs('Daily Dispatch'!$A$7:$A$506,'Daily Dispatch'!$A$7:$A$506,">0"),lqty,IFERROR(SUMIF('Daily Dispatch'!$A$7:$A$506,ldate,'Daily Dispatch'!L7:L506),0),datestr,IF(ldate=TODAY(),"Today",IF(ldate=TODAY()-1,"Yesterday",TEXT(ldate,"DD MMM"))),datestr&" — "&lqty&" units"),"No data yet") -> No data yet | O17: =IFERROR(IF(E17=0,"—",TEXT(ROUND((F17+G17)/E17*100,1),"0.0")&"%"),"—") -> — | P17: =IFERROR(IF(E17=0,"—",TEXT(ROUND(G17/E17*100,1),"0.0")&"%"),"—") -> — | Q17: =F17 -> 0 | R17: =IFERROR(IF(I17=0,"Set Max Level",MAX(0,I17-H17)),"—") -> Set Max Level | S17: =IFERROR(IF(I17=0,"—",IF(H17<I17*0.25,"🔴 ORDER NOW",IF(H17<I17*0.5,"⚠️ Plan Reorder","✅ OK"))),"—") -> —
A18: 12 | B18: Power Shot Oil | C18: 0 | D18: =IFERROR(SUM('Stock In'!AM:AM),0) -> 0 | E18: =IFERROR(SUM('Daily Dispatch'!M:M),0) -> 0 | F18: =IFERROR(SUM('RTO Log'!AI:AI),0) -> 0 | G18: =IFERROR(SUM('RTO Log'!AJ:AJ)+SUM('RTO Log'!AK:AK),0) -> 0 | H18: =C18+D18+F18-G18-E18 -> 0 | J18: =IFERROR(IF(I18=0,"—",TEXT(ROUND(H18/I18*100,1),"0.0")&"%"),"—") -> — | K18: =IFERROR(IF(I18=0,"⬜ Set Max Level",IF(H18/I18>1,"✅ Above Target",IF(H18/I18>=0.75,"✅ On Track",IF(H18/I18>=0.5,"🟡 Watch",IF(H18/I18>=0.25,"🔴 Low Stock","🔴 CRITICAL"))))),"—") -> ⬜ Set Max Level | L18: =IFERROR(SUMPRODUCT((MONTH('Daily Dispatch'!$A$7:$A$506)=IF(MONTH(TODAY())=1,12,MONTH(TODAY())-1))*(YEAR('Daily Dispatch'!$A$7:$A$506)=IF(MONTH(TODAY())=1,YEAR(TODAY())-1,YEAR(TODAY())))*ISNUMBER('Daily Dispatch'!$A$7:$A$506)*'Daily Dispatch'!M7:M506),0) -> 0 | M18: =IFERROR(SUMPRODUCT((MONTH('Daily Dispatch'!$A$7:$A$506)=MONTH(TODAY()))*(YEAR('Daily Dispatch'!$A$7:$A$506)=YEAR(TODAY()))*ISNUMBER('Daily Dispatch'!$A$7:$A$506)*'Daily Dispatch'!M7:M506),0) -> 0 | N18: =IFERROR(let(ldate,maxifs('Daily Dispatch'!$A$7:$A$506,'Daily Dispatch'!$A$7:$A$506,">0"),lqty,IFERROR(SUMIF('Daily Dispatch'!$A$7:$A$506,ldate,'Daily Dispatch'!M7:M506),0),datestr,IF(ldate=TODAY(),"Today",IF(ldate=TODAY()-1,"Yesterday",TEXT(ldate,"DD MMM"))),datestr&" — "&lqty&" units"),"No data yet") -> No data yet | O18: =IFERROR(IF(E18=0,"—",TEXT(ROUND((F18+G18)/E18*100,1),"0.0")&"%"),"—") -> — | P18: =IFERROR(IF(E18=0,"—",TEXT(ROUND(G18/E18*100,1),"0.0")&"%"),"—") -> — | Q18: =F18 -> 0 | R18: =IFERROR(IF(I18=0,"Set Max Level",MAX(0,I18-H18)),"—") -> Set Max Level | S18: =IFERROR(IF(I18=0,"—",IF(H18<I18*0.25,"🔴 ORDER NOW",IF(H18<I18*0.5,"⚠️ Plan Reorder","✅ OK"))),"—") -> —
A21: 📝 Col C (Opening Stock) — sheet setup ke din ek baar manually bharo, phir kabhi nahi. Col I (Max Level) — aap set karo, kabhi bhi update kar sakte ho. Baaki sab auto-calculate.
A23: © 2026 MeDa Partners Pvt Ltd · Systems by MeDa Partners · Brand: Wayveda® · www.meda.partners · Dream. Deliver. Dominate.

Sheet Dispatch Analysis
A1: ✦ MeDa Partners | Dream · Deliver · Dominate Wayveda — Dispatch Analysis | Warehouse Ops
A3: ⚠ Systems by MeDa Partners Pvt Ltd (www.meda.partners) | Brand: Wayveda® | Confidential & Proprietary
A4: Daily Summary | F4: Weekly Summary | J4: Monthly Summary
A6: Date / Period | B6: Bum Plumping Cre | C6: Intimate Whiteni | D6: Chocolate Power | E6: Strawberry Power | F6: Bhasam Power Cap | G6: Power Shots Sach | H6: Hairfall Control | I6: Hairfall Control | J6: Hairfall Control | K6: Anti-Hairfall Ki | L6: Power Roll Oil U | M6: Power Shot Oil | N6: TOTAL
A7: ▼ DAILY — Col A mein date daalo, quantities auto-populate hongi
B8: =IF(A8="","",IFERROR(SUMIF('Daily Dispatch'!$A:$A,A8,'Daily Dispatch'!B:B),0)) | C8: =IF(A8="","",IFERROR(SUMIF('Daily Dispatch'!$A:$A,A8,'Daily Dispatch'!C:C),0)) | D8: =IF(A8="","",IFERROR(SUMIF('Daily Dispatch'!$A:$A,A8,'Daily Dispatch'!D:D),0)) | E8: =IF(A8="","",IFERROR(SUMIF('Daily Dispatch'!$A:$A,A8,'Daily Dispatch'!E:E),0)) | F8: =IF(A8="","",IFERROR(SUMIF('Daily Dispatch'!$A:$A,A8,'Daily Dispatch'!F:F),0)) | G8: =IF(A8="","",IFERROR(SUMIF('Daily Dispatch'!$A:$A,A8,'Daily Dispatch'!G:G),0)) | H8: =IF(A8="","",IFERROR(SUMIF('Daily Dispatch'!$A:$A,A8,'Daily Dispatch'!H:H),0)) | I8: =IF(A8="","",IFERROR(SUMIF('Daily Dispatch'!$A:$A,A8,'Daily Dispatch'!I:I),0)) | J8: =IF(A8="","",IFERROR(SUMIF('Daily Dispatch'!$A:$A,A8,'Daily Dispatch'!J:J),0)) | K8: =IF(A8="","",IFERROR(SUMIF('Daily Dispatch'!$A:$A,A8,'Daily Dispatch'!K:K),0)) | L8: =IF(A8="","",IFERROR(SUMIF('Daily Dispatch'!$A:$A,A8,'Daily Dispatch'!L:L),0)) | M8: =IF(A8="","",IFERROR(SUMIF('Daily Dispatch'!$A:$A,A8,'Daily Dispatch'!M:M),0)) | N8: =IF(A8="","",SUM(B8:M8))
B9: =IF(A9="","",IFERROR(SUMIF('Daily Dispatch'!$A:$A,A9,'Daily Dispatch'!B:B),0)) | C9: =IF(A9="","",IFERROR(SUMIF('Daily Dispatch'!$A:$A,A9,'Daily Dispatch'!C:C),0)) | D9: =IF(A9="","",IFERROR(SUMIF('Daily Dispatch'!$A:$A,A9,'Daily Dispatch'!D:D),0)) | E9: =IF(A9="","",IFERROR(SUMIF('Daily Dispatch'!$A:$A,A9,'Daily Dispatch'!E:E),0)) | F9: =IF(A9="","",IFERROR(SUMIF('Daily Dispatch'!$A:$A,A9,'Daily Dispatch'!F:F),0)) | G9: =IF(A9="","",IFERROR(SUMIF('Daily Dispatch'!$A:$A,A9,'Daily Dispatch'!G:G),0)) | H9: =IF(A9="","",IFERROR(SUMIF('Daily Dispatch'!$A:$A,A9,'Daily Dispatch'!H:H),0)) | I9: =IF(A9="","",IFERROR(SUMIF('Daily Dispatch'!$A:$A,A9,'Daily Dispatch'!I:I),0)) | J9: =IF(A9="","",IFERROR(SUMIF('Daily Dispatch'!$A:$A,A9,'Daily Dispatch'!J:J),0)) | K9: =IF(A9="","",IFERROR(SUMIF('Daily Dispatch'!$A:$A,A9,'Daily Dispatch'!K:K),0)) | L9: =IF(A9="","",IFERROR(SUMIF('Daily Dispatch'!$A:$A,A9,'Daily Dispatch'!L:L),0)) | M9: =IF(A9="","",IFERROR(SUMIF('Daily Dispatch'!$A:$A,A9,'Daily Dispatch'!M:M),0)) | N9: =IF(A9="","",SUM(B9:M9))
B10: =IF(A10="","",IFERROR(SUMIF('Daily Dispatch'!$A:$A,A10,'Daily Dispatch'!B:B),0)) | C10: =IF(A10="","",IFERROR(SUMIF('Daily Dispatch'!$A:$A,A10,'Daily Dispatch'!C:C),0)) | D10: =IF(A10="","",IFERROR(SUMIF('Daily Dispatch'!$A:$A,A10,'Daily Dispatch'!D:D),0)) | E10: =IF(A10="","",IFERROR(SUMIF('Daily Dispatch'!$A:$A,A10,'Daily Dispatch'!E:E),0)) | F10: =IF(A10="","",IFERROR(SUMIF('Daily Dispatch'!$A:$A,A10,'Daily Dispatch'!F:F),0)) | G10: =IF(A10="","",IFERROR(SUMIF('Daily Dispatch'!$A:$A,A10,'Daily Dispatch'!G:G),0)) | H10: =IF(A10="","",IFERROR(SUMIF('Daily Dispatch'!$A:$A,A10,'Daily Dispatch'!H:H),0)) | I10: =IF(A10="","",IFERROR(SUMIF('Daily Dispatch'!$A:$A,A10,'Daily Dispatch'!I:I),0)) | J10: =IF(A10="","",IFERROR(SUMIF('Daily Dispatch'!$A:$A,A10,'Daily Dispatch'!J:J),0)) | K10: =IF(A10="","",IFERROR(SUMIF('Daily Dispatch'!$A:$A,A10,'Daily Dispatch'!K:K),0)) | L10: =IF(A10="","",IFERROR(SUMIF('Daily Dispatch'!$A:$A,A10,'Daily Dispatch'!L:L),0)) | M10: =IF(A10="","",IFERROR(SUMIF('Daily Dispatch'!$A:$A,A10,'Daily Dispatch'!M:M),0)) | N10: =IF(A10="","",SUM(B10:M10))
B11: =IF(A11="","",IFERROR(SUMIF('Daily Dispatch'!$A:$A,A11,'Daily Dispatch'!B:B),0)) | C11: =IF(A11="","",IFERROR(SUMIF('Daily Dispatch'!$A:$A,A11,'Daily Dispatch'!C:C),0)) | D11: =IF(A11="","",IFERROR(SUMIF('Daily Dispatch'!$A:$A,A11,'Daily Dispatch'!D:D),0)) | E11: =IF(A11="","",IFERROR(SUMIF('Daily Dispatch'!$A:$A,A11,'Daily Dispatch'!E:E),0)) | F11: =IF(A11="","",IFERROR(SUMIF('Daily Dispatch'!$A:$A,A11,'Daily Dispatch'!F:F),0)) | G11: =IF(A11="","",IFERROR(SUMIF('Daily Dispatch'!$A:$A,A11,'Daily Dispatch'!G:G),0)) | H11: =IF(A11="","",IFERROR(SUMIF('Daily Dispatch'!$A:$A,A11,'Daily Dispatch'!H:H),0)) | I11: =IF(A11="","",IFERROR(SUMIF('Daily Dispatch'!$A:$A,A11,'Daily Dispatch'!I:I),0)) | J11: =IF(A11="","",IFERROR(SUMIF('Daily Dispatch'!$A:$A,A11,'Daily Dispatch'!J:J),0)) | K11: =IF(A11="","",IFERROR(SUMIF('Daily Dispatch'!$A:$A,A11,'Daily Dispatch'!K:K),0)) | L11: =IF(A11="","",IFERROR(SUMIF('Daily Dispatch'!$A:$A,A11,'Daily Dispatch'!L:L),0)) | M11: =IF(A11="","",IFERROR(SUMIF('Daily Dispatch'!$A:$A,A11,'Daily Dispatch'!M:M),0)) | N11: =IF(A11="","",SUM(B11:M11))
B12: =IF(A12="","",IFERROR(SUMIF('Daily Dispatch'!$A:$A,A12,'Daily Dispatch'!B:B),0)) | C12: =IF(A12="","",IFERROR(SUMIF('Daily Dispatch'!$A:$A,A12,'Daily Dispatch'!C:C),0)) | D12: =IF(A12="","",IFERROR(SUMIF('Daily Dispatch'!$A:$A,A12,'Daily Dispatch'!D:D),0)) | E12: =IF(A12="","",IFERROR(SUMIF('Daily Dispatch'!$A:$A,A12,'Daily Dispatch'!E:E),0)) | F12: =IF(A12="","",IFERROR(SUMIF('Daily Dispatch'!$A:$A,A12,'Daily Dispatch'!F:F),0)) | G12: =IF(A12="","",IFERROR(SUMIF('Daily Dispatch'!$A:$A,A12,'Daily Dispatch'!G:G),0)) | H12: =IF(A12="","",IFERROR(SUMIF('Daily Dispatch'!$A:$A,A12,'Daily Dispatch'!H:H),0)) | I12: =IF(A12="","",IFERROR(SUMIF('Daily Dispatch'!$A:$A,A12,'Daily Dispatch'!I:I),0)) | J12: =IF(A12="","",IFERROR(SUMIF('Daily Dispatch'!$A:$A,A12,'Daily Dispatch'!J:J),0)) | K12: =IF(A12="","",IFERROR(SUMIF('Daily Dispatch'!$A:$A,A12,'Daily Dispatch'!K:K),0)) | L12: =IF(A12="","",IFERROR(SUMIF('Daily Dispatch'!$A:$A,A12,'Daily Dispatch'!L:L),0)) | M12: =IF(A12="","",IFERROR(SUMIF('Daily Dispatch'!$A:$A,A12,'Daily Dispatch'!M:M),0)) | N12: =IF(A12="","",SUM(B12:M12))
B13: =IF(A13="","",IFERROR(SUMIF('Daily Dispatch'!$A:$A,A13,'Daily Dispatch'!B:B),0)) | C13: =IF(A13="","",IFERROR(SUMIF('Daily Dispatch'!$A:$A,A13,'Daily Dispatch'!C:C),0)) | D13: =IF(A13="","",IFERROR(SUMIF('Daily Dispatch'!$A:$A,A13,'Daily Dispatch'!D:D),0)) | E13: =IF(A13="","",IFERROR(SUMIF('Daily Dispatch'!$A:$A,A13,'Daily Dispatch'!E:E),0)) | F13: =IF(A13="","",IFERROR(SUMIF('Daily Dispatch'!$A:$A,A13,'Daily Dispatch'!F:F),0)) | G13: =IF(A13="","",IFERROR(SUMIF('Daily Dispatch'!$A:$A,A13,'Daily Dispatch'!G:G),0)) | H13: =IF(A13="","",IFERROR(SUMIF('Daily Dispatch'!$A:$A,A13,'Daily Dispatch'!H:H),0)) | I13: =IF(A13="","",IFERROR(SUMIF('Daily Dispatch'!$A:$A,A13,'Daily Dispatch'!I:I),0)) | J13: =IF(A13="","",IFERROR(SUMIF('Daily Dispatch'!$A:$A,A13,'Daily Dispatch'!J:J),0)) | K13: =IF(A13="","",IFERROR(SUMIF('Daily Dispatch'!$A:$A,A13,'Daily Dispatch'!K:K),0)) | L13: =IF(A13="","",IFERROR(SUMIF('Daily Dispatch'!$A:$A,A13,'Daily Dispatch'!L:L),0)) | M13: =IF(A13="","",IFERROR(SUMIF('Daily Dispatch'!$A:$A,A13,'Daily Dispatch'!M:M),0)) | N13: =IF(A13="","",SUM(B13:M13))
B14: =IF(A14="","",IFERROR(SUMIF('Daily Dispatch'!$A:$A,A14,'Daily Dispatch'!B:B),0)) | C14: =IF(A14="","",IFERROR(SUMIF('Daily Dispatch'!$A:$A,A14,'Daily Dispatch'!C:C),0)) | D14: =IF(A14="","",IFERROR(SUMIF('Daily Dispatch'!$A:$A,A14,'Daily Dispatch'!D:D),0)) | E14: =IF(A14="","",IFERROR(SUMIF('Daily Dispatch'!$A:$A,A14,'Daily Dispatch'!E:E),0)) | F14: =IF(A14="","",IFERROR(SUMIF('Daily Dispatch'!$A:$A,A14,'Daily Dispatch'!F:F),0)) | G14: =IF(A14="","",IFERROR(SUMIF('Daily Dispatch'!$A:$A,A14,'Daily Dispatch'!G:G),0)) | H14: =IF(A14="","",IFERROR(SUMIF('Daily Dispatch'!$A:$A,A14,'Daily Dispatch'!H:H),0)) | I14: =IF(A14="","",IFERROR(SUMIF('Daily Dispatch'!$A:$A,A14,'Daily Dispatch'!I:I),0)) | J14: =IF(A14="","",IFERROR(SUMIF('Daily Dispatch'!$A:$A,A14,'Daily Dispatch'!J:J),0)) | K14: =IF(A14="","",IFERROR(SUMIF('Daily Dispatch'!$A:$A,A14,'Daily Dispatch'!K:K),0)) | L14: =IF(A14="","",IFERROR(SUMIF('Daily Dispatch'!$A:$A,A14,'Daily Dispatch'!L:L),0)) | M14: =IF(A14="","",IFERROR(SUMIF('Daily Dispatch'!$A:$A,A14,'Daily Dispatch'!M:M),0)) | N14: =IF(A14="","",SUM(B14:M14))
B15: =IF(A15="","",IFERROR(SUMIF('Daily Dispatch'!$A:$A,A15,'Daily Dispatch'!B:B),0)) | C15: =IF(A15="","",IFERROR(SUMIF('Daily Dispatch'!$A:$A,A15,'Daily Dispatch'!C:C),0)) | D15: =IF(A15="","",IFERROR(SUMIF('Daily Dispatch'!$A:$A,A15,'Daily Dispatch'!D:D),0)) | E15: =IF(A15="","",IFERROR(SUMIF('Daily Dispatch'!$A:$A,A15,'Daily Dispatch'!E:E),0)) | F15: =IF(A15="","",IFERROR(SUMIF('Daily Dispatch'!$A:$A,A15,'Daily Dispatch'!F:F),0)) | G15: =IF(A15="","",IFERROR(SUMIF('Daily Dispatch'!$A:$A,A15,'Daily Dispatch'!G:G),0)) | H15: =IF(A15="","",IFERROR(SUMIF('Daily Dispatch'!$A:$A,A15,'Daily Dispatch'!H:H),0)) | I15: =IF(A15="","",IFERROR(SUMIF('Daily Dispatch'!$A:$A,A15,'Daily Dispatch'!I:I),0)) | J15: =IF(A15="","",IFERROR(SUMIF('Daily Dispatch'!$A:$A,A15,'Daily Dispatch'!J:J),0)) | K15: =IF(A15="","",IFERROR(SUMIF('Daily Dispatch'!$A:$A,A15,'Daily Dispatch'!K:K),0)) | L15: =IF(A15="","",IFERROR(SUMIF('Daily Dispatch'!$A:$A,A15,'Daily Dispatch'!L:L),0)) | M15: =IF(A15="","",IFERROR(SUMIF('Daily Dispatch'!$A:$A,A15,'Daily Dispatch'!M:M),0)) | N15: =IF(A15="","",SUM(B15:M15))
B16: =IF(A16="","",IFERROR(SUMIF('Daily Dispatch'!$A:$A,A16,'Daily Dispatch'!B:B),0)) | C16: =IF(A16="","",IFERROR(SUMIF('Daily Dispatch'!$A:$A,A16,'Daily Dispatch'!C:C),0)) | D16: =IF(A16="","",IFERROR(SUMIF('Daily Dispatch'!$A:$A,A16,'Daily Dispatch'!D:D),0)) | E16: =IF(A16="","",IFERROR(SUMIF('Daily Dispatch'!$A:$A,A16,'Daily Dispatch'!E:E),0)) | F16: =IF(A16="","",IFERROR(SUMIF('Daily Dispatch'!$A:$A,A16,'Daily Dispatch'!F:F),0)) | G16: =IF(A16="","",IFERROR(SUMIF('Daily Dispatch'!$A:$A,A16,'Daily Dispatch'!G:G),0)) | H16: =IF(A16="","",IFERROR(SUMIF('Daily Dispatch'!$A:$A,A16,'Daily Dispatch'!H:H),0)) | I16: =IF(A16="","",IFERROR(SUMIF('Daily Dispatch'!$A:$A,A16,'Daily Dispatch'!I:I),0)) | J16: =IF(A16="","",IFERROR(SUMIF('Daily Dispatch'!$A:$A,A16,'Daily Dispatch'!J:J),0)) | K16: =IF(A16="","",IFERROR(SUMIF('Daily Dispatch'!$A:$A,A16,'Daily Dispatch'!K:K),0)) | L16: =IF(A16="","",IFERROR(SUMIF('Daily Dispatch'!$A:$A,A16,'Daily Dispatch'!L:L),0)) | M16: =IF(A16="","",IFERROR(SUMIF('Daily Dispatch'!$A:$A,A16,'Daily Dispatch'!M:M),0)) | N16: =IF(A16="","",SUM(B16:M16))
B17: =IF(A17="","",IFERROR(SUMIF('Daily Dispatch'!$A:$A,A17,'Daily Dispatch'!B:B),0)) | C17: =IF(A17="","",IFERROR(SUMIF('Daily Dispatch'!$A:$A,A17,'Daily Dispatch'!C:C),0)) | D17: =IF(A17="","",IFERROR(SUMIF('Daily Dispatch'!$A:$A,A17,'Daily Dispatch'!D:D),0)) | E17: =IF(A17="","",IFERROR(SUMIF('Daily Dispatch'!$A:$A,A17,'Daily Dispatch'!E:E),0)) | F17: =IF(A17="","",IFERROR(SUMIF('Daily Dispatch'!$A:$A,A17,'Daily Dispatch'!F:F),0)) | G17: =IF(A17="","",IFERROR(SUMIF('Daily Dispatch'!$A:$A,A17,'Daily Dispatch'!G:G),0)) | H17: =IF(A17="","",IFERROR(SUMIF('Daily Dispatch'!$A:$A,A17,'Daily Dispatch'!H:H),0)) | I17: =IF(A17="","",IFERROR(SUMIF('Daily Dispatch'!$A:$A,A17,'Daily Dispatch'!I:I),0)) | J17: =IF(A17="","",IFERROR(SUMIF('Daily Dispatch'!$A:$A,A17,'Daily Dispatch'!J:J),0)) | K17: =IF(A17="","",IFERROR(SUMIF('Daily Dispatch'!$A:$A,A17,'Daily Dispatch'!K:K),0)) | L17: =IF(A17="","",IFERROR(SUMIF('Daily Dispatch'!$A:$A,A17,'Daily Dispatch'!L:L),0)) | M17: =IF(A17="","",IFERROR(SUMIF('Daily Dispatch'!$A:$A,A17,'Daily Dispatch'!M:M),0)) | N17: =IF(A17="","",SUM(B17:M17))
B18: =IF(A18="","",IFERROR(SUMIF('Daily Dispatch'!$A:$A,A18,'Daily Dispatch'!B:B),0)) | C18: =IF(A18="","",IFERROR(SUMIF('Daily Dispatch'!$A:$A,A18,'Daily Dispatch'!C:C),0)) | D18: =IF(A18="","",IFERROR(SUMIF('Daily Dispatch'!$A:$A,A18,'Daily Dispatch'!D:D),0)) | E18: =IF(A18="","",IFERROR(SUMIF('Daily Dispatch'!$A:$A,A18,'Daily Dispatch'!E:E),0)) | F18: =IF(A18="","",IFERROR(SUMIF('Daily Dispatch'!$A:$A,A18,'Daily Dispatch'!F:F),0)) | G18: =IF(A18="","",IFERROR(SUMIF('Daily Dispatch'!$A:$A,A18,'Daily Dispatch'!G:G),0)) | H18: =IF(A18="","",IFERROR(SUMIF('Daily Dispatch'!$A:$A,A18,'Daily Dispatch'!H:H),0)) | I18: =IF(A18="","",IFERROR(SUMIF('Daily Dispatch'!$A:$A,A18,'Daily Dispatch'!I:I),0)) | J18: =IF(A18="","",IFERROR(SUMIF('Daily Dispatch'!$A:$A,A18,'Daily Dispatch'!J:J),0)) | K18: =IF(A18="","",IFERROR(SUMIF('Daily Dispatch'!$A:$A,A18,'Daily Dispatch'!K:K),0)) | L18: =IF(A18="","",IFERROR(SUMIF('Daily Dispatch'!$A:$A,A18,'Daily Dispatch'!L:L),0)) | M18: =IF(A18="","",IFERROR(SUMIF('Daily Dispatch'!$A:$A,A18,'Daily Dispatch'!M:M),0)) | N18: =IF(A18="","",SUM(B18:M18))
B19: =IF(A19="","",IFERROR(SUMIF('Daily Dispatch'!$A:$A,A19,'Daily Dispatch'!B:B),0)) | C19: =IF(A19="","",IFERROR(SUMIF('Daily Dispatch'!$A:$A,A19,'Daily Dispatch'!C:C),0)) | D19: =IF(A19="","",IFERROR(SUMIF('Daily Dispatch'!$A:$A,A19,'Daily Dispatch'!D:D),0)) | E19: =IF(A19="","",IFERROR(SUMIF('Daily Dispatch'!$A:$A,A19,'Daily Dispatch'!E:E),0)) | F19: =IF(A19="","",IFERROR(SUMIF('Daily Dispatch'!$A:$A,A19,'Daily Dispatch'!F:F),0)) | G19: =IF(A19="","",IFERROR(SUMIF('Daily Dispatch'!$A:$A,A19,'Daily Dispatch'!G:G),0)) | H19: =IF(A19="","",IFERROR(SUMIF('Daily Dispatch'!$A:$A,A19,'Daily Dispatch'!H:H),0)) | I19: =IF(A19="","",IFERROR(SUMIF('Daily Dispatch'!$A:$A,A19,'Daily Dispatch'!I:I),0)) | J19: =IF(A19="","",IFERROR(SUMIF('Daily Dispatch'!$A:$A,A19,'Daily Dispatch'!J:J),0)) | K19: =IF(A19="","",IFERROR(SUMIF('Daily Dispatch'!$A:$A,A19,'Daily Dispatch'!K:K),0)) | L19: =IF(A19="","",IFERROR(SUMIF('Daily Dispatch'!$A:$A,A19,'Daily Dispatch'!L:L),0)) | M19: =IF(A19="","",IFERROR(SUMIF('Daily Dispatch'!$A:$A,A19,'Daily Dispatch'!M:M),0)) | N19: =IF(A19="","",SUM(B19:M19))
... B67: =IF(A67="","",IFERROR(SUMIF('Daily Dispatch'!$A:$A,A67,'Daily Dispatch'!B:B),0)) | C67: =IF(A67="","",IFERROR(SUMIF('Daily Dispatch'!$A:$A,A67,'Daily Dispatch'!C:C),0)) | D67: =IF(A67="","",IFERROR(SUMIF('Daily Dispatch'!$A:$A,A67,'Daily Dispatch'!D:D),0)) | E67: =IF(A67="","",IFERROR(SUMIF('Daily Dispatch'!$A:$A,A67,'Daily Dispatch'!E:E),0)) | F67: =IF(A67="","",IFERROR(SUMIF('Daily Dispatch'!$A:$A,A67,'Daily Dispatch'!F:F),0)) | G67: =IF(A67="","",IFERROR(SUMIF('Daily Dispatch'!$A:$A,A67,'Daily Dispatch'!G:G),0)) | H67: =IF(A67="","",IFERROR(SUMIF('Daily Dispatch'!$A:$A,A67,'Daily Dispatch'!H:H),0)) | I67: =IF(A67="","",IFERROR(SUMIF('Daily Dispatch'!$A:$A,A67,'Daily Dispatch'!I:I),0)) | J67: =IF(A67="","",IFERROR(SUMIF('Daily Dispatch'!$A:$A,A67,'Daily Dispatch'!J:J),0)) | K67: =IF(A67="","",IFERROR(SUMIF('Daily Dispatch'!$A:$A,A67,'Daily Dispatch'!K:K),0)) | L67: =IF(A67="","",IFERROR(SUMIF('Daily Dispatch'!$A:$A,A67,'Daily Dispatch'!L:L),0)) | M67: =IF(A67="","",IFERROR(SUMIF('Daily Dispatch'!$A:$A,A67,'Daily Dispatch'!M:M),0)) | N67: =IF(A67="","",SUM(B67:M67))
A70: ▼ WEEKLY — Col A mein 'Week X — DD MMM to DD MMM' format mein likho
N71: =IF(A71="","",SUM(B71:M71))
N72: =IF(A72="","",SUM(B72:M72))
N73: =IF(A73="","",SUM(B73:M73))
N74: =IF(A74="","",SUM(B74:M74))
N75: =IF(A75="","",SUM(B75:M75))
N76: =IF(A76="","",SUM(B76:M76))
N77: =IF(A77="","",SUM(B77:M77))
N78: =IF(A78="","",SUM(B78:M78))
N79: =IF(A79="","",SUM(B79:M79))
N80: =IF(A80="","",SUM(B80:M80))
N81: =IF(A81="","",SUM(B81:M81))
N82: =IF(A82="","",SUM(B82:M82))
... N96: =IF(A96="","",SUM(B96:M96))
A99: ▼ MONTHLY — Auto-calculates via SUMPRODUCT (month+year match)
A100: Apr 2025 | B100: =IFERROR(SUMPRODUCT((TEXT('Daily Dispatch'!$A$7:$A$506,"MMM YYYY")=A100)*ISNUMBER('Daily Dispatch'!$A$7:$A$506)*'Daily Dispatch'!B7:B506),0) -> 0 | C100: =IFERROR(SUMPRODUCT((TEXT('Daily Dispatch'!$A$7:$A$506,"MMM YYYY")=A100)*ISNUMBER('Daily Dispatch'!$A$7:$A$506)*'Daily Dispatch'!C7:C506),0) -> 0 | D100: =IFERROR(SUMPRODUCT((TEXT('Daily Dispatch'!$A$7:$A$506,"MMM YYYY")=A100)*ISNUMBER('Daily Dispatch'!$A$7:$A$506)*'Daily Dispatch'!D7:D506),0) -> 0 | E100: =IFERROR(SUMPRODUCT((TEXT('Daily Dispatch'!$A$7:$A$506,"MMM YYYY")=A100)*ISNUMBER('Daily Dispatch'!$A$7:$A$506)*'Daily Dispatch'!E7:E506),0) -> 0 | F100: =IFERROR(SUMPRODUCT((TEXT('Daily Dispatch'!$A$7:$A$506,"MMM YYYY")=A100)*ISNUMBER('Daily Dispatch'!$A$7:$A$506)*'Daily Dispatch'!F7:F506),0) -> 0 | G100: =IFERROR(SUMPRODUCT((TEXT('Daily Dispatch'!$A$7:$A$506,"MMM YYYY")=A100)*ISNUMBER('Daily Dispatch'!$A$7:$A$506)*'Daily Dispatch'!G7:G506),0) -> 0 | H100: =IFERROR(SUMPRODUCT((TEXT('Daily Dispatch'!$A$7:$A$506,"MMM YYYY")=A100)*ISNUMBER('Daily Dispatch'!$A$7:$A$506)*'Daily Dispatch'!H7:H506),0) -> 0 | I100: =IFERROR(SUMPRODUCT((TEXT('Daily Dispatch'!$A$7:$A$506,"MMM YYYY")=A100)*ISNUMBER('Daily Dispatch'!$A$7:$A$506)*'Daily Dispatch'!I7:I506),0) -> 0 | J100: =IFERROR(SUMPRODUCT((TEXT('Daily Dispatch'!$A$7:$A$506,"MMM YYYY")=A100)*ISNUMBER('Daily Dispatch'!$A$7:$A$506)*'Daily Dispatch'!J7:J506),0) -> 0 | K100: =IFERROR(SUMPRODUCT((TEXT('Daily Dispatch'!$A$7:$A$506,"MMM YYYY")=A100)*ISNUMBER('Daily Dispatch'!$A$7:$A$506)*'Daily Dispatch'!K7:K506),0) -> 0 | L100: =IFERROR(SUMPRODUCT((TEXT('Daily Dispatch'!$A$7:$A$506,"MMM YYYY")=A100)*ISNUMBER('Daily Dispatch'!$A$7:$A$506)*'Daily Dispatch'!L7:L506),0) -> 0 | M100: =IFERROR(SUMPRODUCT((TEXT('Daily Dispatch'!$A$7:$A$506,"MMM YYYY")=A100)*ISNUMBER('Daily Dispatch'!$A$7:$A$506)*'Daily Dispatch'!M7:M506),0) -> 0 | N100: =SUM(B100:M100) -> 0
A101: May 2025 | B101: =IFERROR(SUMPRODUCT((TEXT('Daily Dispatch'!$A$7:$A$506,"MMM YYYY")=A101)*ISNUMBER('Daily Dispatch'!$A$7:$A$506)*'Daily Dispatch'!B7:B506),0) -> 0 | C101: =IFERROR(SUMPRODUCT((TEXT('Daily Dispatch'!$A$7:$A$506,"MMM YYYY")=A101)*ISNUMBER('Daily Dispatch'!$A$7:$A$506)*'Daily Dispatch'!C7:C506),0) -> 0 | D101: =IFERROR(SUMPRODUCT((TEXT('Daily Dispatch'!$A$7:$A$506,"MMM YYYY")=A101)*ISNUMBER('Daily Dispatch'!$A$7:$A$506)*'Daily Dispatch'!D7:D506),0) -> 0 | E101: =IFERROR(SUMPRODUCT((TEXT('Daily Dispatch'!$A$7:$A$506,"MMM YYYY")=A101)*ISNUMBER('Daily Dispatch'!$A$7:$A$506)*'Daily Dispatch'!E7:E506),0) -> 0 | F101: =IFERROR(SUMPRODUCT((TEXT('Daily Dispatch'!$A$7:$A$506,"MMM YYYY")=A101)*ISNUMBER('Daily Dispatch'!$A$7:$A$506)*'Daily Dispatch'!F7:F506),0) -> 0 | G101: =IFERROR(SUMPRODUCT((TEXT('Daily Dispatch'!$A$7:$A$506,"MMM YYYY")=A101)*ISNUMBER('Daily Dispatch'!$A$7:$A$506)*'Daily Dispatch'!G7:G506),0) -> 0 | H101: =IFERROR(SUMPRODUCT((TEXT('Daily Dispatch'!$A$7:$A$506,"MMM YYYY")=A101)*ISNUMBER('Daily Dispatch'!$A$7:$A$506)*'Daily Dispatch'!H7:H506),0) -> 0 | I101: =IFERROR(SUMPRODUCT((TEXT('Daily Dispatch'!$A$7:$A$506,"MMM YYYY")=A101)*ISNUMBER('Daily Dispatch'!$A$7:$A$506)*'Daily Dispatch'!I7:I506),0) -> 0 | J101: =IFERROR(SUMPRODUCT((TEXT('Daily Dispatch'!$A$7:$A$506,"MMM YYYY")=A101)*ISNUMBER('Daily Dispatch'!$A$7:$A$506)*'Daily Dispatch'!J7:J506),0) -> 0 | K101: =IFERROR(SUMPRODUCT((TEXT('Daily Dispatch'!$A$7:$A$506,"MMM YYYY")=A101)*ISNUMBER('Daily Dispatch'!$A$7:$A$506)*'Daily Dispatch'!K7:K506),0) -> 0 | L101: =IFERROR(SUMPRODUCT((TEXT('Daily Dispatch'!$A$7:$A$506,"MMM YYYY")=A101)*ISNUMBER('Daily Dispatch'!$A$7:$A$506)*'Daily Dispatch'!L7:L506),0) -> 0 | M101: =IFERROR(SUMPRODUCT((TEXT('Daily Dispatch'!$A$7:$A$506,"MMM YYYY")=A101)*ISNUMBER('Daily Dispatch'!$A$7:$A$506)*'Daily Dispatch'!M7:M506),0) -> 0 | N101: =SUM(B101:M101) -> 0
A102: Jun 2025 | B102: =IFERROR(SUMPRODUCT((TEXT('Daily Dispatch'!$A$7:$A$506,"MMM YYYY")=A102)*ISNUMBER('Daily Dispatch'!$A$7:$A$506)*'Daily Dispatch'!B7:B506),0) -> 0 | C102: =IFERROR(SUMPRODUCT((TEXT('Daily Dispatch'!$A$7:$A$506,"MMM YYYY")=A102)*ISNUMBER('Daily Dispatch'!$A$7:$A$506)*'Daily Dispatch'!C7:C506),0) -> 0 | D102: =IFERROR(SUMPRODUCT((TEXT('Daily Dispatch'!$A$7:$A$506,"MMM YYYY")=A102)*ISNUMBER('Daily Dispatch'!$A$7:$A$506)*'Daily Dispatch'!D7:D506),0) -> 0 | E102: =IFERROR(SUMPRODUCT((TEXT('Daily Dispatch'!$A$7:$A$506,"MMM YYYY")=A102)*ISNUMBER('Daily Dispatch'!$A$7:$A$506)*'Daily Dispatch'!E7:E506),0) -> 0 | F102: =IFERROR(SUMPRODUCT((TEXT('Daily Dispatch'!$A$7:$A$506,"MMM YYYY")=A102)*ISNUMBER('Daily Dispatch'!$A$7:$A$506)*'Daily Dispatch'!F7:F506),0) -> 0 | G102: =IFERROR(SUMPRODUCT((TEXT('Daily Dispatch'!$A$7:$A$506,"MMM YYYY")=A102)*ISNUMBER('Daily Dispatch'!$A$7:$A$506)*'Daily Dispatch'!G7:G506),0) -> 0 | H102: =IFERROR(SUMPRODUCT((TEXT('Daily Dispatch'!$A$7:$A$506,"MMM YYYY")=A102)*ISNUMBER('Daily Dispatch'!$A$7:$A$506)*'Daily Dispatch'!H7:H506),0) -> 0 | I102: =IFERROR(SUMPRODUCT((TEXT('Daily Dispatch'!$A$7:$A$506,"MMM YYYY")=A102)*ISNUMBER('Daily Dispatch'!$A$7:$A$506)*'Daily Dispatch'!I7:I506),0) -> 0 | J102: =IFERROR(SUMPRODUCT((TEXT('Daily Dispatch'!$A$7:$A$506,"MMM YYYY")=A102)*ISNUMBER('Daily Dispatch'!$A$7:$A$506)*'Daily Dispatch'!J7:J506),0) -> 0 | K102: =IFERROR(SUMPRODUCT((TEXT('Daily Dispatch'!$A$7:$A$506,"MMM YYYY")=A102)*ISNUMBER('Daily Dispatch'!$A$7:$A$506)*'Daily Dispatch'!K7:K506),0) -> 0 | L102: =IFERROR(SUMPRODUCT((TEXT('Daily Dispatch'!$A$7:$A$506,"MMM YYYY")=A102)*ISNUMBER('Daily Dispatch'!$A$7:$A$506)*'Daily Dispatch'!L7:L506),0) -> 0 | M102: =IFERROR(SUMPRODUCT((TEXT('Daily Dispatch'!$A$7:$A$506,"MMM YYYY")=A102)*ISNUMBER('Daily Dispatch'!$A$7:$A$506)*'Daily Dispatch'!M7:M506),0) -> 0 | N102: =SUM(B102:M102) -> 0
